{
 "cells": [
  {
   "cell_type": "code",
   "execution_count": 3,
   "metadata": {},
   "outputs": [],
   "source": [
    "import zarr\n",
    "import numpy as np\n",
    "import anndata\n",
    "import scipy as sp\n",
    "import numpy as np\n",
    "import matplotlib.pyplot as plt\n",
    "import dask\n",
    "from pyseq import image_analysis as ia\n",
    "import warnings\n",
    "warnings.filterwarnings('ignore')\n",
    "from dask.distributed import Client\n",
    "import numba\n",
    "import joblib\n",
    "import skimage\n",
    "import time\n",
    "from joblib import Parallel, delayed\n",
    "from joblib import parallel_backend\n",
    "from dask.distributed import progress\n",
    "%run /gpfs/commons/home/jsingh/util_pyseq.ipynb"
   ]
  },
  {
   "cell_type": "code",
   "execution_count": 4,
   "metadata": {},
   "outputs": [
    {
     "name": "stdout",
     "output_type": "stream",
     "text": [
      "ImageAnalysis::Opened m387ntga2 \n"
     ]
    }
   ],
   "source": [
    "#Loading Data\n",
    "im = ia.get_HiSeqImages(image_path = 'zarrs/m387ntga2.zarr')\n",
    "labels = skimage.io.imread('/gpfs/commons/groups/nygcfaculty/PySeq/20210428_mouse_genotype_2/segmented_sections/m387ntga2_labels.tiff')\n",
    "labels = dask.array.asarray(labels)"
   ]
  },
  {
   "cell_type": "code",
   "execution_count": 5,
   "metadata": {},
   "outputs": [],
   "source": [
    "#format = one_z_plane_obj_step_channel_cycle\n",
    "array_object_list = []\n",
    "name_object_list = []\n",
    "for i in im.im['channel'].values:\n",
    "    for j in im.im['cycle'].values:\n",
    "        #for k #in im.im['obj_step'].values[1]:\n",
    "            k = 8028\n",
    "            name = \"one_x_plane_\"+str(i)+\"_\"+str(j)+\"_\"+str(k)\n",
    "            name_object_list.append(name)\n",
    "            nme = im.im.sel(obj_step = k, cycle=j, channel = i)\n",
    "            array_object_list.append(nme)\n",
    "        "
   ]
  },
  {
   "cell_type": "code",
   "execution_count": 6,
   "metadata": {},
   "outputs": [],
   "source": [
    "############ INITIATING CLUSTER ####################"
   ]
  },
  {
   "cell_type": "code",
   "execution_count": 18,
   "metadata": {},
   "outputs": [],
   "source": [
    "def get_cluster(queue_name = 'pe2', log_dir=None):\n",
    "    \"\"\" Make dask cluster w/ workers = 2 cores, 32 G mem, and 1 hr wall time.\n",
    "\n",
    "        return cluster, client\n",
    "    \"\"\"\n",
    "\n",
    "    if log_dir is None:\n",
    "        log_dir = join(getcwd(),'dask_logs')\n",
    "        makedirs(log_dir, exist_ok=True)\n",
    "\n",
    "    cluster = SLURMCluster(\n",
    "                queue = queue_name, \n",
    "                cores = 12 ,\n",
    "                memory = '128G',\n",
    "                walltime='1:00:00',\n",
    "                log_directory=log_dir)\n",
    "                #extra=[\"--lifetime\", \"55m\", \"--lifetime-stagger\", \"4m\"])\n",
    "    client = Client(cluster)\n",
    "\n",
    "    return cluster, client\n",
    "\n",
    "cluster, client = get_cluster()"
   ]
  },
  {
   "cell_type": "code",
   "execution_count": 19,
   "metadata": {},
   "outputs": [],
   "source": [
    "cluster.scale(15) "
   ]
  },
  {
   "cell_type": "code",
   "execution_count": 20,
   "metadata": {},
   "outputs": [
    {
     "name": "stdout",
     "output_type": "stream",
     "text": [
      "http://10.4.202.10:42570/status\n"
     ]
    }
   ],
   "source": [
    "print(cluster.dashboard_link) # Or specify cores or memory directly"
   ]
  },
  {
   "cell_type": "code",
   "execution_count": 21,
   "metadata": {},
   "outputs": [],
   "source": [
    "plane = array_object_list[0] #sample plane "
   ]
  },
  {
   "cell_type": "code",
   "execution_count": 12,
   "metadata": {},
   "outputs": [],
   "source": [
    "#Way 1: Using Data As Is (No Persit) with Dask Futures\n",
    "\n",
    "plane = array_object_list[0]\n",
    "def get_pixels(lab):\n",
    "    m = plane.values[labels == lab+1].mean()\n",
    "    return m\n",
    "\n",
    "futures = client.map(get_pixels, range(5))\n",
    "progress(futures)\n",
    "\n",
    "result_list = np.zeros(20)\n",
    "for i in range(len(futures)):\n",
    "    result_list[i] = futures[i].result()\n",
    "    \n",
    "    "
   ]
  },
  {
   "cell_type": "code",
   "execution_count": 13,
   "metadata": {},
   "outputs": [],
   "source": [
    "#Way 2: Using with Dask Persist with Dask Futures\n",
    "\n",
    "plane_persisted = array_object_list[0].persist()\n",
    "def get_pixels(lab):\n",
    "    m = plane_persisted.values[labels == lab+1].mean()\n",
    "    return m\n",
    "from dask.distributed import progress\n",
    "futures = client.map(get_pixels, range(5))\n",
    "progress(futures)\n",
    "\n",
    "\n",
    "result_list = np.zeros(20)\n",
    "for i in range(len(futures)):\n",
    "    result_list[i] = futures[i].result()"
   ]
  },
  {
   "cell_type": "code",
   "execution_count": null,
   "metadata": {},
   "outputs": [],
   "source": [
    "%%time\n",
    "#Way 3: Computing the same using dask compute without persisting Data\n",
    "\n",
    "def get_pixels(lab):\n",
    "    m = plane.values[labels == lab+1].mean()\n",
    "    return m\n",
    "\n",
    "with parallel_backend('dask',scheduler_host=cluster.scheduler._address):\n",
    "    results = Parallel(n_jobs=-1)(delayed(get_pixels_persisted)(lab) for lab in range(100))"
   ]
  },
  {
   "cell_type": "code",
   "execution_count": null,
   "metadata": {},
   "outputs": [],
   "source": [
    "%%time\n",
    "#Way 4: Computing way 3 with persist\n",
    "\n",
    "def get_pixels(lab):\n",
    "    m = plane_persisted.values[labels == lab+1].mean()\n",
    "    return m\n",
    "\n",
    "with parallel_backend('dask',scheduler_host=cluster.scheduler._address):\n",
    "    results = Parallel(n_jobs=-1)(delayed(get_pixels_persisted)(lab) for lab in range(100))"
   ]
  },
  {
   "cell_type": "code",
   "execution_count": 63,
   "metadata": {},
   "outputs": [],
   "source": [
    "dk = dask.array.asarray(plane.values)"
   ]
  },
  {
   "cell_type": "code",
   "execution_count": 64,
   "metadata": {},
   "outputs": [],
   "source": [
    "#Way 5: Dask Masked Array\n",
    "dk = dask.array.asarray(plane.values)\n",
    "def get_pixels(lab):\n",
    "    m = dask.array.ma.masked_array(dk,np.squeeze([labels == lab]))\n",
    "    mv = dask.array.mean(m)\n",
    "    return mv\n",
    "\n",
    "futures = client.map(get_pixels, range(5))\n",
    "\n",
    "result_list = np.zeros(20)\n",
    "for i in range(len(futures)):\n",
    "    result_list[i] = futures[i].result()\n",
    "    \n",
    "    \n"
   ]
  },
  {
   "cell_type": "code",
   "execution_count": 65,
   "metadata": {},
   "outputs": [
    {
     "ename": "NameError",
     "evalue": "name 'persisted_plane' is not defined",
     "output_type": "error",
     "traceback": [
      "\u001b[0;31m---------------------------------------------------------------------------\u001b[0m",
      "\u001b[0;31mNameError\u001b[0m                                 Traceback (most recent call last)",
      "Input \u001b[0;32mIn [65]\u001b[0m, in \u001b[0;36m<cell line: 2>\u001b[0;34m()\u001b[0m\n\u001b[1;32m      1\u001b[0m \u001b[38;5;66;03m#Way 6: Dask Masked Array With Persist \u001b[39;00m\n\u001b[0;32m----> 2\u001b[0m dk \u001b[38;5;241m=\u001b[39m dask\u001b[38;5;241m.\u001b[39marray\u001b[38;5;241m.\u001b[39masarray(\u001b[43mpersisted_plane\u001b[49m\u001b[38;5;241m.\u001b[39mvalues)\n\u001b[1;32m      3\u001b[0m \u001b[38;5;28;01mdef\u001b[39;00m \u001b[38;5;21mget_pixels\u001b[39m(lab):\n\u001b[1;32m      4\u001b[0m     m \u001b[38;5;241m=\u001b[39m dask\u001b[38;5;241m.\u001b[39marray\u001b[38;5;241m.\u001b[39mma\u001b[38;5;241m.\u001b[39mmasked_array(dk,np\u001b[38;5;241m.\u001b[39msqueeze([labels \u001b[38;5;241m==\u001b[39m lab]))\n",
      "\u001b[0;31mNameError\u001b[0m: name 'persisted_plane' is not defined"
     ]
    }
   ],
   "source": [
    "#Way 6: Dask Masked Array With Persist \n",
    "dk = dask.array.asarray(persisted_plane.values)\n",
    "def get_pixels(lab):\n",
    "    m = dask.array.ma.masked_array(dk,np.squeeze([labels == lab]))\n",
    "    mv = dask.array.mean(m)\n",
    "    return mv\n",
    "\n",
    "futures = client.map(get_pixels, range(5))\n",
    "\n",
    "result_list = np.zeros(20)\n",
    "for i in range(len(futures)):\n",
    "    result_list[i] = futures[i].result()\n",
    "    \n",
    "\n"
   ]
  },
  {
   "cell_type": "code",
   "execution_count": 70,
   "metadata": {},
   "outputs": [
    {
     "name": "stderr",
     "output_type": "stream",
     "text": [
      "2022-06-22 23:50:17,858 - tornado.application - ERROR - Exception in callback functools.partial(<bound method IOLoop._discard_future_result of <zmq.eventloop.ioloop.ZMQIOLoop object at 0x7fb5a03a0880>>, <Task finished name='Task-2092088' coro=<DaskDistributedBackend.apply_async.<locals>.f() done, defined at /gpfs/commons/home/jsingh/.conda/envs/spatial/lib/python3.9/site-packages/joblib/_dask.py:323> exception=TypeError('Delayed objects of unspecified length are not iterable')>)\n",
      "Traceback (most recent call last):\n",
      "  File \"/gpfs/commons/home/jsingh/.conda/envs/spatial/lib/python3.9/site-packages/tornado/ioloop.py\", line 741, in _run_callback\n",
      "    ret = callback()\n",
      "  File \"/gpfs/commons/home/jsingh/.conda/envs/spatial/lib/python3.9/site-packages/tornado/ioloop.py\", line 765, in _discard_future_result\n",
      "    future.result()\n",
      "  File \"/gpfs/commons/home/jsingh/.conda/envs/spatial/lib/python3.9/site-packages/joblib/_dask.py\", line 324, in f\n",
      "    batch, tasks = await self._to_func_args(func)\n",
      "  File \"/gpfs/commons/home/jsingh/.conda/envs/spatial/lib/python3.9/site-packages/joblib/_dask.py\", line 310, in _to_func_args\n",
      "    for f, args, kwargs in func.items:\n",
      "  File \"/gpfs/commons/home/jsingh/.conda/envs/spatial/lib/python3.9/site-packages/dask/delayed.py\", line 581, in __iter__\n",
      "    raise TypeError(\"Delayed objects of unspecified length are not iterable\")\n",
      "TypeError: Delayed objects of unspecified length are not iterable\n",
      "2022-06-22 23:50:17,902 - tornado.application - ERROR - Exception in callback functools.partial(<bound method IOLoop._discard_future_result of <zmq.eventloop.ioloop.ZMQIOLoop object at 0x7fb5a03a0880>>, <Task finished name='Task-2092089' coro=<DaskDistributedBackend.apply_async.<locals>.f() done, defined at /gpfs/commons/home/jsingh/.conda/envs/spatial/lib/python3.9/site-packages/joblib/_dask.py:323> exception=TypeError('Delayed objects of unspecified length are not iterable')>)\n",
      "Traceback (most recent call last):\n",
      "  File \"/gpfs/commons/home/jsingh/.conda/envs/spatial/lib/python3.9/site-packages/tornado/ioloop.py\", line 741, in _run_callback\n",
      "    ret = callback()\n",
      "  File \"/gpfs/commons/home/jsingh/.conda/envs/spatial/lib/python3.9/site-packages/tornado/ioloop.py\", line 765, in _discard_future_result\n",
      "    future.result()\n",
      "  File \"/gpfs/commons/home/jsingh/.conda/envs/spatial/lib/python3.9/site-packages/joblib/_dask.py\", line 324, in f\n",
      "    batch, tasks = await self._to_func_args(func)\n",
      "  File \"/gpfs/commons/home/jsingh/.conda/envs/spatial/lib/python3.9/site-packages/joblib/_dask.py\", line 310, in _to_func_args\n",
      "    for f, args, kwargs in func.items:\n",
      "  File \"/gpfs/commons/home/jsingh/.conda/envs/spatial/lib/python3.9/site-packages/dask/delayed.py\", line 581, in __iter__\n",
      "    raise TypeError(\"Delayed objects of unspecified length are not iterable\")\n",
      "TypeError: Delayed objects of unspecified length are not iterable\n",
      "2022-06-22 23:50:17,904 - tornado.application - ERROR - Exception in callback functools.partial(<bound method IOLoop._discard_future_result of <zmq.eventloop.ioloop.ZMQIOLoop object at 0x7fb5a03a0880>>, <Task finished name='Task-2092090' coro=<DaskDistributedBackend.apply_async.<locals>.f() done, defined at /gpfs/commons/home/jsingh/.conda/envs/spatial/lib/python3.9/site-packages/joblib/_dask.py:323> exception=TypeError('Delayed objects of unspecified length are not iterable')>)\n",
      "Traceback (most recent call last):\n",
      "  File \"/gpfs/commons/home/jsingh/.conda/envs/spatial/lib/python3.9/site-packages/tornado/ioloop.py\", line 741, in _run_callback\n",
      "    ret = callback()\n",
      "  File \"/gpfs/commons/home/jsingh/.conda/envs/spatial/lib/python3.9/site-packages/tornado/ioloop.py\", line 765, in _discard_future_result\n",
      "    future.result()\n",
      "  File \"/gpfs/commons/home/jsingh/.conda/envs/spatial/lib/python3.9/site-packages/joblib/_dask.py\", line 324, in f\n",
      "    batch, tasks = await self._to_func_args(func)\n",
      "  File \"/gpfs/commons/home/jsingh/.conda/envs/spatial/lib/python3.9/site-packages/joblib/_dask.py\", line 310, in _to_func_args\n",
      "    for f, args, kwargs in func.items:\n",
      "  File \"/gpfs/commons/home/jsingh/.conda/envs/spatial/lib/python3.9/site-packages/dask/delayed.py\", line 581, in __iter__\n",
      "    raise TypeError(\"Delayed objects of unspecified length are not iterable\")\n",
      "TypeError: Delayed objects of unspecified length are not iterable\n",
      "2022-06-22 23:50:17,905 - tornado.application - ERROR - Exception in callback functools.partial(<bound method IOLoop._discard_future_result of <zmq.eventloop.ioloop.ZMQIOLoop object at 0x7fb5a03a0880>>, <Task finished name='Task-2092091' coro=<DaskDistributedBackend.apply_async.<locals>.f() done, defined at /gpfs/commons/home/jsingh/.conda/envs/spatial/lib/python3.9/site-packages/joblib/_dask.py:323> exception=TypeError('Delayed objects of unspecified length are not iterable')>)\n",
      "Traceback (most recent call last):\n",
      "  File \"/gpfs/commons/home/jsingh/.conda/envs/spatial/lib/python3.9/site-packages/tornado/ioloop.py\", line 741, in _run_callback\n",
      "    ret = callback()\n",
      "  File \"/gpfs/commons/home/jsingh/.conda/envs/spatial/lib/python3.9/site-packages/tornado/ioloop.py\", line 765, in _discard_future_result\n",
      "    future.result()\n",
      "  File \"/gpfs/commons/home/jsingh/.conda/envs/spatial/lib/python3.9/site-packages/joblib/_dask.py\", line 324, in f\n",
      "    batch, tasks = await self._to_func_args(func)\n",
      "  File \"/gpfs/commons/home/jsingh/.conda/envs/spatial/lib/python3.9/site-packages/joblib/_dask.py\", line 310, in _to_func_args\n",
      "    for f, args, kwargs in func.items:\n",
      "  File \"/gpfs/commons/home/jsingh/.conda/envs/spatial/lib/python3.9/site-packages/dask/delayed.py\", line 581, in __iter__\n",
      "    raise TypeError(\"Delayed objects of unspecified length are not iterable\")\n",
      "TypeError: Delayed objects of unspecified length are not iterable\n",
      "2022-06-22 23:50:17,907 - tornado.application - ERROR - Exception in callback functools.partial(<bound method IOLoop._discard_future_result of <zmq.eventloop.ioloop.ZMQIOLoop object at 0x7fb5a03a0880>>, <Task finished name='Task-2092092' coro=<DaskDistributedBackend.apply_async.<locals>.f() done, defined at /gpfs/commons/home/jsingh/.conda/envs/spatial/lib/python3.9/site-packages/joblib/_dask.py:323> exception=TypeError('Delayed objects of unspecified length are not iterable')>)\n",
      "Traceback (most recent call last):\n",
      "  File \"/gpfs/commons/home/jsingh/.conda/envs/spatial/lib/python3.9/site-packages/tornado/ioloop.py\", line 741, in _run_callback\n",
      "    ret = callback()\n",
      "  File \"/gpfs/commons/home/jsingh/.conda/envs/spatial/lib/python3.9/site-packages/tornado/ioloop.py\", line 765, in _discard_future_result\n",
      "    future.result()\n",
      "  File \"/gpfs/commons/home/jsingh/.conda/envs/spatial/lib/python3.9/site-packages/joblib/_dask.py\", line 324, in f\n",
      "    batch, tasks = await self._to_func_args(func)\n",
      "  File \"/gpfs/commons/home/jsingh/.conda/envs/spatial/lib/python3.9/site-packages/joblib/_dask.py\", line 310, in _to_func_args\n",
      "    for f, args, kwargs in func.items:\n",
      "  File \"/gpfs/commons/home/jsingh/.conda/envs/spatial/lib/python3.9/site-packages/dask/delayed.py\", line 581, in __iter__\n",
      "    raise TypeError(\"Delayed objects of unspecified length are not iterable\")\n",
      "TypeError: Delayed objects of unspecified length are not iterable\n",
      "2022-06-22 23:50:17,910 - tornado.application - ERROR - Exception in callback functools.partial(<bound method IOLoop._discard_future_result of <zmq.eventloop.ioloop.ZMQIOLoop object at 0x7fb5a03a0880>>, <Task finished name='Task-2092107' coro=<DaskDistributedBackend.apply_async.<locals>.f() done, defined at /gpfs/commons/home/jsingh/.conda/envs/spatial/lib/python3.9/site-packages/joblib/_dask.py:323> exception=TypeError('Delayed objects of unspecified length are not iterable')>)\n",
      "Traceback (most recent call last):\n",
      "  File \"/gpfs/commons/home/jsingh/.conda/envs/spatial/lib/python3.9/site-packages/tornado/ioloop.py\", line 741, in _run_callback\n",
      "    ret = callback()\n",
      "  File \"/gpfs/commons/home/jsingh/.conda/envs/spatial/lib/python3.9/site-packages/tornado/ioloop.py\", line 765, in _discard_future_result\n",
      "    future.result()\n",
      "  File \"/gpfs/commons/home/jsingh/.conda/envs/spatial/lib/python3.9/site-packages/joblib/_dask.py\", line 324, in f\n",
      "    batch, tasks = await self._to_func_args(func)\n",
      "  File \"/gpfs/commons/home/jsingh/.conda/envs/spatial/lib/python3.9/site-packages/joblib/_dask.py\", line 310, in _to_func_args\n",
      "    for f, args, kwargs in func.items:\n",
      "  File \"/gpfs/commons/home/jsingh/.conda/envs/spatial/lib/python3.9/site-packages/dask/delayed.py\", line 581, in __iter__\n",
      "    raise TypeError(\"Delayed objects of unspecified length are not iterable\")\n",
      "TypeError: Delayed objects of unspecified length are not iterable\n"
     ]
    },
    {
     "name": "stderr",
     "output_type": "stream",
     "text": [
      "2022-06-22 23:50:17,912 - tornado.application - ERROR - Exception in callback functools.partial(<bound method IOLoop._discard_future_result of <zmq.eventloop.ioloop.ZMQIOLoop object at 0x7fb5a03a0880>>, <Task finished name='Task-2092108' coro=<DaskDistributedBackend.apply_async.<locals>.f() done, defined at /gpfs/commons/home/jsingh/.conda/envs/spatial/lib/python3.9/site-packages/joblib/_dask.py:323> exception=TypeError('Delayed objects of unspecified length are not iterable')>)\n",
      "Traceback (most recent call last):\n",
      "  File \"/gpfs/commons/home/jsingh/.conda/envs/spatial/lib/python3.9/site-packages/tornado/ioloop.py\", line 741, in _run_callback\n",
      "    ret = callback()\n",
      "  File \"/gpfs/commons/home/jsingh/.conda/envs/spatial/lib/python3.9/site-packages/tornado/ioloop.py\", line 765, in _discard_future_result\n",
      "    future.result()\n",
      "  File \"/gpfs/commons/home/jsingh/.conda/envs/spatial/lib/python3.9/site-packages/joblib/_dask.py\", line 324, in f\n",
      "    batch, tasks = await self._to_func_args(func)\n",
      "  File \"/gpfs/commons/home/jsingh/.conda/envs/spatial/lib/python3.9/site-packages/joblib/_dask.py\", line 310, in _to_func_args\n",
      "    for f, args, kwargs in func.items:\n",
      "  File \"/gpfs/commons/home/jsingh/.conda/envs/spatial/lib/python3.9/site-packages/dask/delayed.py\", line 581, in __iter__\n",
      "    raise TypeError(\"Delayed objects of unspecified length are not iterable\")\n",
      "TypeError: Delayed objects of unspecified length are not iterable\n",
      "2022-06-22 23:50:17,913 - tornado.application - ERROR - Exception in callback functools.partial(<bound method IOLoop._discard_future_result of <zmq.eventloop.ioloop.ZMQIOLoop object at 0x7fb5a03a0880>>, <Task finished name='Task-2092109' coro=<DaskDistributedBackend.apply_async.<locals>.f() done, defined at /gpfs/commons/home/jsingh/.conda/envs/spatial/lib/python3.9/site-packages/joblib/_dask.py:323> exception=TypeError('Delayed objects of unspecified length are not iterable')>)\n",
      "Traceback (most recent call last):\n",
      "  File \"/gpfs/commons/home/jsingh/.conda/envs/spatial/lib/python3.9/site-packages/tornado/ioloop.py\", line 741, in _run_callback\n",
      "    ret = callback()\n",
      "  File \"/gpfs/commons/home/jsingh/.conda/envs/spatial/lib/python3.9/site-packages/tornado/ioloop.py\", line 765, in _discard_future_result\n",
      "    future.result()\n",
      "  File \"/gpfs/commons/home/jsingh/.conda/envs/spatial/lib/python3.9/site-packages/joblib/_dask.py\", line 324, in f\n",
      "    batch, tasks = await self._to_func_args(func)\n",
      "  File \"/gpfs/commons/home/jsingh/.conda/envs/spatial/lib/python3.9/site-packages/joblib/_dask.py\", line 310, in _to_func_args\n",
      "    for f, args, kwargs in func.items:\n",
      "  File \"/gpfs/commons/home/jsingh/.conda/envs/spatial/lib/python3.9/site-packages/dask/delayed.py\", line 581, in __iter__\n",
      "    raise TypeError(\"Delayed objects of unspecified length are not iterable\")\n",
      "TypeError: Delayed objects of unspecified length are not iterable\n",
      "2022-06-22 23:50:17,915 - tornado.application - ERROR - Exception in callback functools.partial(<bound method IOLoop._discard_future_result of <zmq.eventloop.ioloop.ZMQIOLoop object at 0x7fb5a03a0880>>, <Task finished name='Task-2092110' coro=<DaskDistributedBackend.apply_async.<locals>.f() done, defined at /gpfs/commons/home/jsingh/.conda/envs/spatial/lib/python3.9/site-packages/joblib/_dask.py:323> exception=TypeError('Delayed objects of unspecified length are not iterable')>)\n",
      "Traceback (most recent call last):\n",
      "  File \"/gpfs/commons/home/jsingh/.conda/envs/spatial/lib/python3.9/site-packages/tornado/ioloop.py\", line 741, in _run_callback\n",
      "    ret = callback()\n",
      "  File \"/gpfs/commons/home/jsingh/.conda/envs/spatial/lib/python3.9/site-packages/tornado/ioloop.py\", line 765, in _discard_future_result\n",
      "    future.result()\n",
      "  File \"/gpfs/commons/home/jsingh/.conda/envs/spatial/lib/python3.9/site-packages/joblib/_dask.py\", line 324, in f\n",
      "    batch, tasks = await self._to_func_args(func)\n",
      "  File \"/gpfs/commons/home/jsingh/.conda/envs/spatial/lib/python3.9/site-packages/joblib/_dask.py\", line 310, in _to_func_args\n",
      "    for f, args, kwargs in func.items:\n",
      "  File \"/gpfs/commons/home/jsingh/.conda/envs/spatial/lib/python3.9/site-packages/dask/delayed.py\", line 581, in __iter__\n",
      "    raise TypeError(\"Delayed objects of unspecified length are not iterable\")\n",
      "TypeError: Delayed objects of unspecified length are not iterable\n",
      "2022-06-22 23:50:17,916 - tornado.application - ERROR - Exception in callback functools.partial(<bound method IOLoop._discard_future_result of <zmq.eventloop.ioloop.ZMQIOLoop object at 0x7fb5a03a0880>>, <Task finished name='Task-2092111' coro=<DaskDistributedBackend.apply_async.<locals>.f() done, defined at /gpfs/commons/home/jsingh/.conda/envs/spatial/lib/python3.9/site-packages/joblib/_dask.py:323> exception=TypeError('Delayed objects of unspecified length are not iterable')>)\n",
      "Traceback (most recent call last):\n",
      "  File \"/gpfs/commons/home/jsingh/.conda/envs/spatial/lib/python3.9/site-packages/tornado/ioloop.py\", line 741, in _run_callback\n",
      "    ret = callback()\n",
      "  File \"/gpfs/commons/home/jsingh/.conda/envs/spatial/lib/python3.9/site-packages/tornado/ioloop.py\", line 765, in _discard_future_result\n",
      "    future.result()\n",
      "  File \"/gpfs/commons/home/jsingh/.conda/envs/spatial/lib/python3.9/site-packages/joblib/_dask.py\", line 324, in f\n",
      "    batch, tasks = await self._to_func_args(func)\n",
      "  File \"/gpfs/commons/home/jsingh/.conda/envs/spatial/lib/python3.9/site-packages/joblib/_dask.py\", line 310, in _to_func_args\n",
      "    for f, args, kwargs in func.items:\n",
      "  File \"/gpfs/commons/home/jsingh/.conda/envs/spatial/lib/python3.9/site-packages/dask/delayed.py\", line 581, in __iter__\n",
      "    raise TypeError(\"Delayed objects of unspecified length are not iterable\")\n",
      "TypeError: Delayed objects of unspecified length are not iterable\n",
      "2022-06-22 23:50:17,917 - tornado.application - ERROR - Exception in callback functools.partial(<bound method IOLoop._discard_future_result of <zmq.eventloop.ioloop.ZMQIOLoop object at 0x7fb5a03a0880>>, <Task finished name='Task-2092112' coro=<DaskDistributedBackend.apply_async.<locals>.f() done, defined at /gpfs/commons/home/jsingh/.conda/envs/spatial/lib/python3.9/site-packages/joblib/_dask.py:323> exception=TypeError('Delayed objects of unspecified length are not iterable')>)\n",
      "Traceback (most recent call last):\n",
      "  File \"/gpfs/commons/home/jsingh/.conda/envs/spatial/lib/python3.9/site-packages/tornado/ioloop.py\", line 741, in _run_callback\n",
      "    ret = callback()\n",
      "  File \"/gpfs/commons/home/jsingh/.conda/envs/spatial/lib/python3.9/site-packages/tornado/ioloop.py\", line 765, in _discard_future_result\n",
      "    future.result()\n",
      "  File \"/gpfs/commons/home/jsingh/.conda/envs/spatial/lib/python3.9/site-packages/joblib/_dask.py\", line 324, in f\n",
      "    batch, tasks = await self._to_func_args(func)\n",
      "  File \"/gpfs/commons/home/jsingh/.conda/envs/spatial/lib/python3.9/site-packages/joblib/_dask.py\", line 310, in _to_func_args\n",
      "    for f, args, kwargs in func.items:\n",
      "  File \"/gpfs/commons/home/jsingh/.conda/envs/spatial/lib/python3.9/site-packages/dask/delayed.py\", line 581, in __iter__\n",
      "    raise TypeError(\"Delayed objects of unspecified length are not iterable\")\n",
      "TypeError: Delayed objects of unspecified length are not iterable\n",
      "2022-06-22 23:50:17,918 - tornado.application - ERROR - Exception in callback functools.partial(<bound method IOLoop._discard_future_result of <zmq.eventloop.ioloop.ZMQIOLoop object at 0x7fb5a03a0880>>, <Task finished name='Task-2092113' coro=<DaskDistributedBackend.apply_async.<locals>.f() done, defined at /gpfs/commons/home/jsingh/.conda/envs/spatial/lib/python3.9/site-packages/joblib/_dask.py:323> exception=TypeError('Delayed objects of unspecified length are not iterable')>)\n",
      "Traceback (most recent call last):\n",
      "  File \"/gpfs/commons/home/jsingh/.conda/envs/spatial/lib/python3.9/site-packages/tornado/ioloop.py\", line 741, in _run_callback\n",
      "    ret = callback()\n",
      "  File \"/gpfs/commons/home/jsingh/.conda/envs/spatial/lib/python3.9/site-packages/tornado/ioloop.py\", line 765, in _discard_future_result\n",
      "    future.result()\n",
      "  File \"/gpfs/commons/home/jsingh/.conda/envs/spatial/lib/python3.9/site-packages/joblib/_dask.py\", line 324, in f\n",
      "    batch, tasks = await self._to_func_args(func)\n",
      "  File \"/gpfs/commons/home/jsingh/.conda/envs/spatial/lib/python3.9/site-packages/joblib/_dask.py\", line 310, in _to_func_args\n",
      "    for f, args, kwargs in func.items:\n",
      "  File \"/gpfs/commons/home/jsingh/.conda/envs/spatial/lib/python3.9/site-packages/dask/delayed.py\", line 581, in __iter__\n",
      "    raise TypeError(\"Delayed objects of unspecified length are not iterable\")\n",
      "TypeError: Delayed objects of unspecified length are not iterable\n"
     ]
    },
    {
     "name": "stderr",
     "output_type": "stream",
     "text": [
      "2022-06-22 23:50:17,919 - tornado.application - ERROR - Exception in callback functools.partial(<bound method IOLoop._discard_future_result of <zmq.eventloop.ioloop.ZMQIOLoop object at 0x7fb5a03a0880>>, <Task finished name='Task-2092114' coro=<DaskDistributedBackend.apply_async.<locals>.f() done, defined at /gpfs/commons/home/jsingh/.conda/envs/spatial/lib/python3.9/site-packages/joblib/_dask.py:323> exception=TypeError('Delayed objects of unspecified length are not iterable')>)\n",
      "Traceback (most recent call last):\n",
      "  File \"/gpfs/commons/home/jsingh/.conda/envs/spatial/lib/python3.9/site-packages/tornado/ioloop.py\", line 741, in _run_callback\n",
      "    ret = callback()\n",
      "  File \"/gpfs/commons/home/jsingh/.conda/envs/spatial/lib/python3.9/site-packages/tornado/ioloop.py\", line 765, in _discard_future_result\n",
      "    future.result()\n",
      "  File \"/gpfs/commons/home/jsingh/.conda/envs/spatial/lib/python3.9/site-packages/joblib/_dask.py\", line 324, in f\n",
      "    batch, tasks = await self._to_func_args(func)\n",
      "  File \"/gpfs/commons/home/jsingh/.conda/envs/spatial/lib/python3.9/site-packages/joblib/_dask.py\", line 310, in _to_func_args\n",
      "    for f, args, kwargs in func.items:\n",
      "  File \"/gpfs/commons/home/jsingh/.conda/envs/spatial/lib/python3.9/site-packages/dask/delayed.py\", line 581, in __iter__\n",
      "    raise TypeError(\"Delayed objects of unspecified length are not iterable\")\n",
      "TypeError: Delayed objects of unspecified length are not iterable\n",
      "2022-06-22 23:50:17,920 - tornado.application - ERROR - Exception in callback functools.partial(<bound method IOLoop._discard_future_result of <zmq.eventloop.ioloop.ZMQIOLoop object at 0x7fb5a03a0880>>, <Task finished name='Task-2092115' coro=<DaskDistributedBackend.apply_async.<locals>.f() done, defined at /gpfs/commons/home/jsingh/.conda/envs/spatial/lib/python3.9/site-packages/joblib/_dask.py:323> exception=TypeError('Delayed objects of unspecified length are not iterable')>)\n",
      "Traceback (most recent call last):\n",
      "  File \"/gpfs/commons/home/jsingh/.conda/envs/spatial/lib/python3.9/site-packages/tornado/ioloop.py\", line 741, in _run_callback\n",
      "    ret = callback()\n",
      "  File \"/gpfs/commons/home/jsingh/.conda/envs/spatial/lib/python3.9/site-packages/tornado/ioloop.py\", line 765, in _discard_future_result\n",
      "    future.result()\n",
      "  File \"/gpfs/commons/home/jsingh/.conda/envs/spatial/lib/python3.9/site-packages/joblib/_dask.py\", line 324, in f\n",
      "    batch, tasks = await self._to_func_args(func)\n",
      "  File \"/gpfs/commons/home/jsingh/.conda/envs/spatial/lib/python3.9/site-packages/joblib/_dask.py\", line 310, in _to_func_args\n",
      "    for f, args, kwargs in func.items:\n",
      "  File \"/gpfs/commons/home/jsingh/.conda/envs/spatial/lib/python3.9/site-packages/dask/delayed.py\", line 581, in __iter__\n",
      "    raise TypeError(\"Delayed objects of unspecified length are not iterable\")\n",
      "TypeError: Delayed objects of unspecified length are not iterable\n",
      "2022-06-22 23:50:17,922 - tornado.application - ERROR - Exception in callback functools.partial(<bound method IOLoop._discard_future_result of <zmq.eventloop.ioloop.ZMQIOLoop object at 0x7fb5a03a0880>>, <Task finished name='Task-2092116' coro=<DaskDistributedBackend.apply_async.<locals>.f() done, defined at /gpfs/commons/home/jsingh/.conda/envs/spatial/lib/python3.9/site-packages/joblib/_dask.py:323> exception=TypeError('Delayed objects of unspecified length are not iterable')>)\n",
      "Traceback (most recent call last):\n",
      "  File \"/gpfs/commons/home/jsingh/.conda/envs/spatial/lib/python3.9/site-packages/tornado/ioloop.py\", line 741, in _run_callback\n",
      "    ret = callback()\n",
      "  File \"/gpfs/commons/home/jsingh/.conda/envs/spatial/lib/python3.9/site-packages/tornado/ioloop.py\", line 765, in _discard_future_result\n",
      "    future.result()\n",
      "  File \"/gpfs/commons/home/jsingh/.conda/envs/spatial/lib/python3.9/site-packages/joblib/_dask.py\", line 324, in f\n",
      "    batch, tasks = await self._to_func_args(func)\n",
      "  File \"/gpfs/commons/home/jsingh/.conda/envs/spatial/lib/python3.9/site-packages/joblib/_dask.py\", line 310, in _to_func_args\n",
      "    for f, args, kwargs in func.items:\n",
      "  File \"/gpfs/commons/home/jsingh/.conda/envs/spatial/lib/python3.9/site-packages/dask/delayed.py\", line 581, in __iter__\n",
      "    raise TypeError(\"Delayed objects of unspecified length are not iterable\")\n",
      "TypeError: Delayed objects of unspecified length are not iterable\n",
      "2022-06-22 23:50:17,923 - tornado.application - ERROR - Exception in callback functools.partial(<bound method IOLoop._discard_future_result of <zmq.eventloop.ioloop.ZMQIOLoop object at 0x7fb5a03a0880>>, <Task finished name='Task-2092117' coro=<DaskDistributedBackend.apply_async.<locals>.f() done, defined at /gpfs/commons/home/jsingh/.conda/envs/spatial/lib/python3.9/site-packages/joblib/_dask.py:323> exception=TypeError('Delayed objects of unspecified length are not iterable')>)\n",
      "Traceback (most recent call last):\n",
      "  File \"/gpfs/commons/home/jsingh/.conda/envs/spatial/lib/python3.9/site-packages/tornado/ioloop.py\", line 741, in _run_callback\n",
      "    ret = callback()\n",
      "  File \"/gpfs/commons/home/jsingh/.conda/envs/spatial/lib/python3.9/site-packages/tornado/ioloop.py\", line 765, in _discard_future_result\n",
      "    future.result()\n",
      "  File \"/gpfs/commons/home/jsingh/.conda/envs/spatial/lib/python3.9/site-packages/joblib/_dask.py\", line 324, in f\n",
      "    batch, tasks = await self._to_func_args(func)\n",
      "  File \"/gpfs/commons/home/jsingh/.conda/envs/spatial/lib/python3.9/site-packages/joblib/_dask.py\", line 310, in _to_func_args\n",
      "    for f, args, kwargs in func.items:\n",
      "  File \"/gpfs/commons/home/jsingh/.conda/envs/spatial/lib/python3.9/site-packages/dask/delayed.py\", line 581, in __iter__\n",
      "    raise TypeError(\"Delayed objects of unspecified length are not iterable\")\n",
      "TypeError: Delayed objects of unspecified length are not iterable\n",
      "2022-06-22 23:50:17,924 - tornado.application - ERROR - Exception in callback functools.partial(<bound method IOLoop._discard_future_result of <zmq.eventloop.ioloop.ZMQIOLoop object at 0x7fb5a03a0880>>, <Task finished name='Task-2092118' coro=<DaskDistributedBackend.apply_async.<locals>.f() done, defined at /gpfs/commons/home/jsingh/.conda/envs/spatial/lib/python3.9/site-packages/joblib/_dask.py:323> exception=TypeError('Delayed objects of unspecified length are not iterable')>)\n",
      "Traceback (most recent call last):\n",
      "  File \"/gpfs/commons/home/jsingh/.conda/envs/spatial/lib/python3.9/site-packages/tornado/ioloop.py\", line 741, in _run_callback\n",
      "    ret = callback()\n",
      "  File \"/gpfs/commons/home/jsingh/.conda/envs/spatial/lib/python3.9/site-packages/tornado/ioloop.py\", line 765, in _discard_future_result\n",
      "    future.result()\n",
      "  File \"/gpfs/commons/home/jsingh/.conda/envs/spatial/lib/python3.9/site-packages/joblib/_dask.py\", line 324, in f\n",
      "    batch, tasks = await self._to_func_args(func)\n",
      "  File \"/gpfs/commons/home/jsingh/.conda/envs/spatial/lib/python3.9/site-packages/joblib/_dask.py\", line 310, in _to_func_args\n",
      "    for f, args, kwargs in func.items:\n",
      "  File \"/gpfs/commons/home/jsingh/.conda/envs/spatial/lib/python3.9/site-packages/dask/delayed.py\", line 581, in __iter__\n",
      "    raise TypeError(\"Delayed objects of unspecified length are not iterable\")\n",
      "TypeError: Delayed objects of unspecified length are not iterable\n",
      "2022-06-22 23:50:17,925 - tornado.application - ERROR - Exception in callback functools.partial(<bound method IOLoop._discard_future_result of <zmq.eventloop.ioloop.ZMQIOLoop object at 0x7fb5a03a0880>>, <Task finished name='Task-2092119' coro=<DaskDistributedBackend.apply_async.<locals>.f() done, defined at /gpfs/commons/home/jsingh/.conda/envs/spatial/lib/python3.9/site-packages/joblib/_dask.py:323> exception=TypeError('Delayed objects of unspecified length are not iterable')>)\n",
      "Traceback (most recent call last):\n",
      "  File \"/gpfs/commons/home/jsingh/.conda/envs/spatial/lib/python3.9/site-packages/tornado/ioloop.py\", line 741, in _run_callback\n",
      "    ret = callback()\n",
      "  File \"/gpfs/commons/home/jsingh/.conda/envs/spatial/lib/python3.9/site-packages/tornado/ioloop.py\", line 765, in _discard_future_result\n",
      "    future.result()\n",
      "  File \"/gpfs/commons/home/jsingh/.conda/envs/spatial/lib/python3.9/site-packages/joblib/_dask.py\", line 324, in f\n",
      "    batch, tasks = await self._to_func_args(func)\n",
      "  File \"/gpfs/commons/home/jsingh/.conda/envs/spatial/lib/python3.9/site-packages/joblib/_dask.py\", line 310, in _to_func_args\n",
      "    for f, args, kwargs in func.items:\n",
      "  File \"/gpfs/commons/home/jsingh/.conda/envs/spatial/lib/python3.9/site-packages/dask/delayed.py\", line 581, in __iter__\n",
      "    raise TypeError(\"Delayed objects of unspecified length are not iterable\")\n",
      "TypeError: Delayed objects of unspecified length are not iterable\n"
     ]
    },
    {
     "name": "stderr",
     "output_type": "stream",
     "text": [
      "2022-06-22 23:50:17,926 - tornado.application - ERROR - Exception in callback functools.partial(<bound method IOLoop._discard_future_result of <zmq.eventloop.ioloop.ZMQIOLoop object at 0x7fb5a03a0880>>, <Task finished name='Task-2092120' coro=<DaskDistributedBackend.apply_async.<locals>.f() done, defined at /gpfs/commons/home/jsingh/.conda/envs/spatial/lib/python3.9/site-packages/joblib/_dask.py:323> exception=TypeError('Delayed objects of unspecified length are not iterable')>)\n",
      "Traceback (most recent call last):\n",
      "  File \"/gpfs/commons/home/jsingh/.conda/envs/spatial/lib/python3.9/site-packages/tornado/ioloop.py\", line 741, in _run_callback\n",
      "    ret = callback()\n",
      "  File \"/gpfs/commons/home/jsingh/.conda/envs/spatial/lib/python3.9/site-packages/tornado/ioloop.py\", line 765, in _discard_future_result\n",
      "    future.result()\n",
      "  File \"/gpfs/commons/home/jsingh/.conda/envs/spatial/lib/python3.9/site-packages/joblib/_dask.py\", line 324, in f\n",
      "    batch, tasks = await self._to_func_args(func)\n",
      "  File \"/gpfs/commons/home/jsingh/.conda/envs/spatial/lib/python3.9/site-packages/joblib/_dask.py\", line 310, in _to_func_args\n",
      "    for f, args, kwargs in func.items:\n",
      "  File \"/gpfs/commons/home/jsingh/.conda/envs/spatial/lib/python3.9/site-packages/dask/delayed.py\", line 581, in __iter__\n",
      "    raise TypeError(\"Delayed objects of unspecified length are not iterable\")\n",
      "TypeError: Delayed objects of unspecified length are not iterable\n",
      "2022-06-22 23:50:17,927 - tornado.application - ERROR - Exception in callback functools.partial(<bound method IOLoop._discard_future_result of <zmq.eventloop.ioloop.ZMQIOLoop object at 0x7fb5a03a0880>>, <Task finished name='Task-2092121' coro=<DaskDistributedBackend.apply_async.<locals>.f() done, defined at /gpfs/commons/home/jsingh/.conda/envs/spatial/lib/python3.9/site-packages/joblib/_dask.py:323> exception=TypeError('Delayed objects of unspecified length are not iterable')>)\n",
      "Traceback (most recent call last):\n",
      "  File \"/gpfs/commons/home/jsingh/.conda/envs/spatial/lib/python3.9/site-packages/tornado/ioloop.py\", line 741, in _run_callback\n",
      "    ret = callback()\n",
      "  File \"/gpfs/commons/home/jsingh/.conda/envs/spatial/lib/python3.9/site-packages/tornado/ioloop.py\", line 765, in _discard_future_result\n",
      "    future.result()\n",
      "  File \"/gpfs/commons/home/jsingh/.conda/envs/spatial/lib/python3.9/site-packages/joblib/_dask.py\", line 324, in f\n",
      "    batch, tasks = await self._to_func_args(func)\n",
      "  File \"/gpfs/commons/home/jsingh/.conda/envs/spatial/lib/python3.9/site-packages/joblib/_dask.py\", line 310, in _to_func_args\n",
      "    for f, args, kwargs in func.items:\n",
      "  File \"/gpfs/commons/home/jsingh/.conda/envs/spatial/lib/python3.9/site-packages/dask/delayed.py\", line 581, in __iter__\n",
      "    raise TypeError(\"Delayed objects of unspecified length are not iterable\")\n",
      "TypeError: Delayed objects of unspecified length are not iterable\n",
      "2022-06-22 23:50:17,927 - tornado.application - ERROR - Exception in callback functools.partial(<bound method IOLoop._discard_future_result of <zmq.eventloop.ioloop.ZMQIOLoop object at 0x7fb5a03a0880>>, <Task finished name='Task-2092122' coro=<DaskDistributedBackend.apply_async.<locals>.f() done, defined at /gpfs/commons/home/jsingh/.conda/envs/spatial/lib/python3.9/site-packages/joblib/_dask.py:323> exception=TypeError('Delayed objects of unspecified length are not iterable')>)\n",
      "Traceback (most recent call last):\n",
      "  File \"/gpfs/commons/home/jsingh/.conda/envs/spatial/lib/python3.9/site-packages/tornado/ioloop.py\", line 741, in _run_callback\n",
      "    ret = callback()\n",
      "  File \"/gpfs/commons/home/jsingh/.conda/envs/spatial/lib/python3.9/site-packages/tornado/ioloop.py\", line 765, in _discard_future_result\n",
      "    future.result()\n",
      "  File \"/gpfs/commons/home/jsingh/.conda/envs/spatial/lib/python3.9/site-packages/joblib/_dask.py\", line 324, in f\n",
      "    batch, tasks = await self._to_func_args(func)\n",
      "  File \"/gpfs/commons/home/jsingh/.conda/envs/spatial/lib/python3.9/site-packages/joblib/_dask.py\", line 310, in _to_func_args\n",
      "    for f, args, kwargs in func.items:\n",
      "  File \"/gpfs/commons/home/jsingh/.conda/envs/spatial/lib/python3.9/site-packages/dask/delayed.py\", line 581, in __iter__\n",
      "    raise TypeError(\"Delayed objects of unspecified length are not iterable\")\n",
      "TypeError: Delayed objects of unspecified length are not iterable\n",
      "2022-06-22 23:50:17,929 - tornado.application - ERROR - Exception in callback functools.partial(<bound method IOLoop._discard_future_result of <zmq.eventloop.ioloop.ZMQIOLoop object at 0x7fb5a03a0880>>, <Task finished name='Task-2092123' coro=<DaskDistributedBackend.apply_async.<locals>.f() done, defined at /gpfs/commons/home/jsingh/.conda/envs/spatial/lib/python3.9/site-packages/joblib/_dask.py:323> exception=TypeError('Delayed objects of unspecified length are not iterable')>)\n",
      "Traceback (most recent call last):\n",
      "  File \"/gpfs/commons/home/jsingh/.conda/envs/spatial/lib/python3.9/site-packages/tornado/ioloop.py\", line 741, in _run_callback\n",
      "    ret = callback()\n",
      "  File \"/gpfs/commons/home/jsingh/.conda/envs/spatial/lib/python3.9/site-packages/tornado/ioloop.py\", line 765, in _discard_future_result\n",
      "    future.result()\n",
      "  File \"/gpfs/commons/home/jsingh/.conda/envs/spatial/lib/python3.9/site-packages/joblib/_dask.py\", line 324, in f\n",
      "    batch, tasks = await self._to_func_args(func)\n",
      "  File \"/gpfs/commons/home/jsingh/.conda/envs/spatial/lib/python3.9/site-packages/joblib/_dask.py\", line 310, in _to_func_args\n",
      "    for f, args, kwargs in func.items:\n",
      "  File \"/gpfs/commons/home/jsingh/.conda/envs/spatial/lib/python3.9/site-packages/dask/delayed.py\", line 581, in __iter__\n",
      "    raise TypeError(\"Delayed objects of unspecified length are not iterable\")\n",
      "TypeError: Delayed objects of unspecified length are not iterable\n",
      "2022-06-22 23:50:17,930 - tornado.application - ERROR - Exception in callback functools.partial(<bound method IOLoop._discard_future_result of <zmq.eventloop.ioloop.ZMQIOLoop object at 0x7fb5a03a0880>>, <Task finished name='Task-2092124' coro=<DaskDistributedBackend.apply_async.<locals>.f() done, defined at /gpfs/commons/home/jsingh/.conda/envs/spatial/lib/python3.9/site-packages/joblib/_dask.py:323> exception=TypeError('Delayed objects of unspecified length are not iterable')>)\n",
      "Traceback (most recent call last):\n",
      "  File \"/gpfs/commons/home/jsingh/.conda/envs/spatial/lib/python3.9/site-packages/tornado/ioloop.py\", line 741, in _run_callback\n",
      "    ret = callback()\n",
      "  File \"/gpfs/commons/home/jsingh/.conda/envs/spatial/lib/python3.9/site-packages/tornado/ioloop.py\", line 765, in _discard_future_result\n",
      "    future.result()\n",
      "  File \"/gpfs/commons/home/jsingh/.conda/envs/spatial/lib/python3.9/site-packages/joblib/_dask.py\", line 324, in f\n",
      "    batch, tasks = await self._to_func_args(func)\n",
      "  File \"/gpfs/commons/home/jsingh/.conda/envs/spatial/lib/python3.9/site-packages/joblib/_dask.py\", line 310, in _to_func_args\n",
      "    for f, args, kwargs in func.items:\n",
      "  File \"/gpfs/commons/home/jsingh/.conda/envs/spatial/lib/python3.9/site-packages/dask/delayed.py\", line 581, in __iter__\n",
      "    raise TypeError(\"Delayed objects of unspecified length are not iterable\")\n",
      "TypeError: Delayed objects of unspecified length are not iterable\n",
      "2022-06-22 23:50:17,932 - tornado.application - ERROR - Exception in callback functools.partial(<bound method IOLoop._discard_future_result of <zmq.eventloop.ioloop.ZMQIOLoop object at 0x7fb5a03a0880>>, <Task finished name='Task-2092125' coro=<DaskDistributedBackend.apply_async.<locals>.f() done, defined at /gpfs/commons/home/jsingh/.conda/envs/spatial/lib/python3.9/site-packages/joblib/_dask.py:323> exception=TypeError('Delayed objects of unspecified length are not iterable')>)\n",
      "Traceback (most recent call last):\n",
      "  File \"/gpfs/commons/home/jsingh/.conda/envs/spatial/lib/python3.9/site-packages/tornado/ioloop.py\", line 741, in _run_callback\n",
      "    ret = callback()\n",
      "  File \"/gpfs/commons/home/jsingh/.conda/envs/spatial/lib/python3.9/site-packages/tornado/ioloop.py\", line 765, in _discard_future_result\n",
      "    future.result()\n",
      "  File \"/gpfs/commons/home/jsingh/.conda/envs/spatial/lib/python3.9/site-packages/joblib/_dask.py\", line 324, in f\n",
      "    batch, tasks = await self._to_func_args(func)\n",
      "  File \"/gpfs/commons/home/jsingh/.conda/envs/spatial/lib/python3.9/site-packages/joblib/_dask.py\", line 310, in _to_func_args\n",
      "    for f, args, kwargs in func.items:\n",
      "  File \"/gpfs/commons/home/jsingh/.conda/envs/spatial/lib/python3.9/site-packages/dask/delayed.py\", line 581, in __iter__\n",
      "    raise TypeError(\"Delayed objects of unspecified length are not iterable\")\n",
      "TypeError: Delayed objects of unspecified length are not iterable\n"
     ]
    },
    {
     "name": "stderr",
     "output_type": "stream",
     "text": [
      "2022-06-22 23:50:17,933 - tornado.application - ERROR - Exception in callback functools.partial(<bound method IOLoop._discard_future_result of <zmq.eventloop.ioloop.ZMQIOLoop object at 0x7fb5a03a0880>>, <Task finished name='Task-2092126' coro=<DaskDistributedBackend.apply_async.<locals>.f() done, defined at /gpfs/commons/home/jsingh/.conda/envs/spatial/lib/python3.9/site-packages/joblib/_dask.py:323> exception=TypeError('Delayed objects of unspecified length are not iterable')>)\n",
      "Traceback (most recent call last):\n",
      "  File \"/gpfs/commons/home/jsingh/.conda/envs/spatial/lib/python3.9/site-packages/tornado/ioloop.py\", line 741, in _run_callback\n",
      "    ret = callback()\n",
      "  File \"/gpfs/commons/home/jsingh/.conda/envs/spatial/lib/python3.9/site-packages/tornado/ioloop.py\", line 765, in _discard_future_result\n",
      "    future.result()\n",
      "  File \"/gpfs/commons/home/jsingh/.conda/envs/spatial/lib/python3.9/site-packages/joblib/_dask.py\", line 324, in f\n",
      "    batch, tasks = await self._to_func_args(func)\n",
      "  File \"/gpfs/commons/home/jsingh/.conda/envs/spatial/lib/python3.9/site-packages/joblib/_dask.py\", line 310, in _to_func_args\n",
      "    for f, args, kwargs in func.items:\n",
      "  File \"/gpfs/commons/home/jsingh/.conda/envs/spatial/lib/python3.9/site-packages/dask/delayed.py\", line 581, in __iter__\n",
      "    raise TypeError(\"Delayed objects of unspecified length are not iterable\")\n",
      "TypeError: Delayed objects of unspecified length are not iterable\n",
      "2022-06-22 23:50:17,934 - tornado.application - ERROR - Exception in callback functools.partial(<bound method IOLoop._discard_future_result of <zmq.eventloop.ioloop.ZMQIOLoop object at 0x7fb5a03a0880>>, <Task finished name='Task-2092127' coro=<DaskDistributedBackend.apply_async.<locals>.f() done, defined at /gpfs/commons/home/jsingh/.conda/envs/spatial/lib/python3.9/site-packages/joblib/_dask.py:323> exception=TypeError('Delayed objects of unspecified length are not iterable')>)\n",
      "Traceback (most recent call last):\n",
      "  File \"/gpfs/commons/home/jsingh/.conda/envs/spatial/lib/python3.9/site-packages/tornado/ioloop.py\", line 741, in _run_callback\n",
      "    ret = callback()\n",
      "  File \"/gpfs/commons/home/jsingh/.conda/envs/spatial/lib/python3.9/site-packages/tornado/ioloop.py\", line 765, in _discard_future_result\n",
      "    future.result()\n",
      "  File \"/gpfs/commons/home/jsingh/.conda/envs/spatial/lib/python3.9/site-packages/joblib/_dask.py\", line 324, in f\n",
      "    batch, tasks = await self._to_func_args(func)\n",
      "  File \"/gpfs/commons/home/jsingh/.conda/envs/spatial/lib/python3.9/site-packages/joblib/_dask.py\", line 310, in _to_func_args\n",
      "    for f, args, kwargs in func.items:\n",
      "  File \"/gpfs/commons/home/jsingh/.conda/envs/spatial/lib/python3.9/site-packages/dask/delayed.py\", line 581, in __iter__\n",
      "    raise TypeError(\"Delayed objects of unspecified length are not iterable\")\n",
      "TypeError: Delayed objects of unspecified length are not iterable\n",
      "2022-06-22 23:50:17,935 - tornado.application - ERROR - Exception in callback functools.partial(<bound method IOLoop._discard_future_result of <zmq.eventloop.ioloop.ZMQIOLoop object at 0x7fb5a03a0880>>, <Task finished name='Task-2092128' coro=<DaskDistributedBackend.apply_async.<locals>.f() done, defined at /gpfs/commons/home/jsingh/.conda/envs/spatial/lib/python3.9/site-packages/joblib/_dask.py:323> exception=TypeError('Delayed objects of unspecified length are not iterable')>)\n",
      "Traceback (most recent call last):\n",
      "  File \"/gpfs/commons/home/jsingh/.conda/envs/spatial/lib/python3.9/site-packages/tornado/ioloop.py\", line 741, in _run_callback\n",
      "    ret = callback()\n",
      "  File \"/gpfs/commons/home/jsingh/.conda/envs/spatial/lib/python3.9/site-packages/tornado/ioloop.py\", line 765, in _discard_future_result\n",
      "    future.result()\n",
      "  File \"/gpfs/commons/home/jsingh/.conda/envs/spatial/lib/python3.9/site-packages/joblib/_dask.py\", line 324, in f\n",
      "    batch, tasks = await self._to_func_args(func)\n",
      "  File \"/gpfs/commons/home/jsingh/.conda/envs/spatial/lib/python3.9/site-packages/joblib/_dask.py\", line 310, in _to_func_args\n",
      "    for f, args, kwargs in func.items:\n",
      "  File \"/gpfs/commons/home/jsingh/.conda/envs/spatial/lib/python3.9/site-packages/dask/delayed.py\", line 581, in __iter__\n",
      "    raise TypeError(\"Delayed objects of unspecified length are not iterable\")\n",
      "TypeError: Delayed objects of unspecified length are not iterable\n",
      "2022-06-22 23:50:17,936 - tornado.application - ERROR - Exception in callback functools.partial(<bound method IOLoop._discard_future_result of <zmq.eventloop.ioloop.ZMQIOLoop object at 0x7fb5a03a0880>>, <Task finished name='Task-2092129' coro=<DaskDistributedBackend.apply_async.<locals>.f() done, defined at /gpfs/commons/home/jsingh/.conda/envs/spatial/lib/python3.9/site-packages/joblib/_dask.py:323> exception=TypeError('Delayed objects of unspecified length are not iterable')>)\n",
      "Traceback (most recent call last):\n",
      "  File \"/gpfs/commons/home/jsingh/.conda/envs/spatial/lib/python3.9/site-packages/tornado/ioloop.py\", line 741, in _run_callback\n",
      "    ret = callback()\n",
      "  File \"/gpfs/commons/home/jsingh/.conda/envs/spatial/lib/python3.9/site-packages/tornado/ioloop.py\", line 765, in _discard_future_result\n",
      "    future.result()\n",
      "  File \"/gpfs/commons/home/jsingh/.conda/envs/spatial/lib/python3.9/site-packages/joblib/_dask.py\", line 324, in f\n",
      "    batch, tasks = await self._to_func_args(func)\n",
      "  File \"/gpfs/commons/home/jsingh/.conda/envs/spatial/lib/python3.9/site-packages/joblib/_dask.py\", line 310, in _to_func_args\n",
      "    for f, args, kwargs in func.items:\n",
      "  File \"/gpfs/commons/home/jsingh/.conda/envs/spatial/lib/python3.9/site-packages/dask/delayed.py\", line 581, in __iter__\n",
      "    raise TypeError(\"Delayed objects of unspecified length are not iterable\")\n",
      "TypeError: Delayed objects of unspecified length are not iterable\n",
      "2022-06-22 23:50:17,937 - tornado.application - ERROR - Exception in callback functools.partial(<bound method IOLoop._discard_future_result of <zmq.eventloop.ioloop.ZMQIOLoop object at 0x7fb5a03a0880>>, <Task finished name='Task-2092130' coro=<DaskDistributedBackend.apply_async.<locals>.f() done, defined at /gpfs/commons/home/jsingh/.conda/envs/spatial/lib/python3.9/site-packages/joblib/_dask.py:323> exception=TypeError('Delayed objects of unspecified length are not iterable')>)\n",
      "Traceback (most recent call last):\n",
      "  File \"/gpfs/commons/home/jsingh/.conda/envs/spatial/lib/python3.9/site-packages/tornado/ioloop.py\", line 741, in _run_callback\n",
      "    ret = callback()\n",
      "  File \"/gpfs/commons/home/jsingh/.conda/envs/spatial/lib/python3.9/site-packages/tornado/ioloop.py\", line 765, in _discard_future_result\n",
      "    future.result()\n",
      "  File \"/gpfs/commons/home/jsingh/.conda/envs/spatial/lib/python3.9/site-packages/joblib/_dask.py\", line 324, in f\n",
      "    batch, tasks = await self._to_func_args(func)\n",
      "  File \"/gpfs/commons/home/jsingh/.conda/envs/spatial/lib/python3.9/site-packages/joblib/_dask.py\", line 310, in _to_func_args\n",
      "    for f, args, kwargs in func.items:\n",
      "  File \"/gpfs/commons/home/jsingh/.conda/envs/spatial/lib/python3.9/site-packages/dask/delayed.py\", line 581, in __iter__\n",
      "    raise TypeError(\"Delayed objects of unspecified length are not iterable\")\n",
      "TypeError: Delayed objects of unspecified length are not iterable\n",
      "2022-06-22 23:50:17,939 - tornado.application - ERROR - Exception in callback functools.partial(<bound method IOLoop._discard_future_result of <zmq.eventloop.ioloop.ZMQIOLoop object at 0x7fb5a03a0880>>, <Task finished name='Task-2092131' coro=<DaskDistributedBackend.apply_async.<locals>.f() done, defined at /gpfs/commons/home/jsingh/.conda/envs/spatial/lib/python3.9/site-packages/joblib/_dask.py:323> exception=TypeError('Delayed objects of unspecified length are not iterable')>)\n",
      "Traceback (most recent call last):\n",
      "  File \"/gpfs/commons/home/jsingh/.conda/envs/spatial/lib/python3.9/site-packages/tornado/ioloop.py\", line 741, in _run_callback\n",
      "    ret = callback()\n",
      "  File \"/gpfs/commons/home/jsingh/.conda/envs/spatial/lib/python3.9/site-packages/tornado/ioloop.py\", line 765, in _discard_future_result\n",
      "    future.result()\n",
      "  File \"/gpfs/commons/home/jsingh/.conda/envs/spatial/lib/python3.9/site-packages/joblib/_dask.py\", line 324, in f\n",
      "    batch, tasks = await self._to_func_args(func)\n",
      "  File \"/gpfs/commons/home/jsingh/.conda/envs/spatial/lib/python3.9/site-packages/joblib/_dask.py\", line 310, in _to_func_args\n",
      "    for f, args, kwargs in func.items:\n",
      "  File \"/gpfs/commons/home/jsingh/.conda/envs/spatial/lib/python3.9/site-packages/dask/delayed.py\", line 581, in __iter__\n",
      "    raise TypeError(\"Delayed objects of unspecified length are not iterable\")\n",
      "TypeError: Delayed objects of unspecified length are not iterable\n"
     ]
    },
    {
     "name": "stderr",
     "output_type": "stream",
     "text": [
      "2022-06-22 23:50:17,940 - tornado.application - ERROR - Exception in callback functools.partial(<bound method IOLoop._discard_future_result of <zmq.eventloop.ioloop.ZMQIOLoop object at 0x7fb5a03a0880>>, <Task finished name='Task-2092132' coro=<DaskDistributedBackend.apply_async.<locals>.f() done, defined at /gpfs/commons/home/jsingh/.conda/envs/spatial/lib/python3.9/site-packages/joblib/_dask.py:323> exception=TypeError('Delayed objects of unspecified length are not iterable')>)\n",
      "Traceback (most recent call last):\n",
      "  File \"/gpfs/commons/home/jsingh/.conda/envs/spatial/lib/python3.9/site-packages/tornado/ioloop.py\", line 741, in _run_callback\n",
      "    ret = callback()\n",
      "  File \"/gpfs/commons/home/jsingh/.conda/envs/spatial/lib/python3.9/site-packages/tornado/ioloop.py\", line 765, in _discard_future_result\n",
      "    future.result()\n",
      "  File \"/gpfs/commons/home/jsingh/.conda/envs/spatial/lib/python3.9/site-packages/joblib/_dask.py\", line 324, in f\n",
      "    batch, tasks = await self._to_func_args(func)\n",
      "  File \"/gpfs/commons/home/jsingh/.conda/envs/spatial/lib/python3.9/site-packages/joblib/_dask.py\", line 310, in _to_func_args\n",
      "    for f, args, kwargs in func.items:\n",
      "  File \"/gpfs/commons/home/jsingh/.conda/envs/spatial/lib/python3.9/site-packages/dask/delayed.py\", line 581, in __iter__\n",
      "    raise TypeError(\"Delayed objects of unspecified length are not iterable\")\n",
      "TypeError: Delayed objects of unspecified length are not iterable\n",
      "2022-06-22 23:50:17,941 - tornado.application - ERROR - Exception in callback functools.partial(<bound method IOLoop._discard_future_result of <zmq.eventloop.ioloop.ZMQIOLoop object at 0x7fb5a03a0880>>, <Task finished name='Task-2092133' coro=<DaskDistributedBackend.apply_async.<locals>.f() done, defined at /gpfs/commons/home/jsingh/.conda/envs/spatial/lib/python3.9/site-packages/joblib/_dask.py:323> exception=TypeError('Delayed objects of unspecified length are not iterable')>)\n",
      "Traceback (most recent call last):\n",
      "  File \"/gpfs/commons/home/jsingh/.conda/envs/spatial/lib/python3.9/site-packages/tornado/ioloop.py\", line 741, in _run_callback\n",
      "    ret = callback()\n",
      "  File \"/gpfs/commons/home/jsingh/.conda/envs/spatial/lib/python3.9/site-packages/tornado/ioloop.py\", line 765, in _discard_future_result\n",
      "    future.result()\n",
      "  File \"/gpfs/commons/home/jsingh/.conda/envs/spatial/lib/python3.9/site-packages/joblib/_dask.py\", line 324, in f\n",
      "    batch, tasks = await self._to_func_args(func)\n",
      "  File \"/gpfs/commons/home/jsingh/.conda/envs/spatial/lib/python3.9/site-packages/joblib/_dask.py\", line 310, in _to_func_args\n",
      "    for f, args, kwargs in func.items:\n",
      "  File \"/gpfs/commons/home/jsingh/.conda/envs/spatial/lib/python3.9/site-packages/dask/delayed.py\", line 581, in __iter__\n",
      "    raise TypeError(\"Delayed objects of unspecified length are not iterable\")\n",
      "TypeError: Delayed objects of unspecified length are not iterable\n",
      "2022-06-22 23:50:17,942 - tornado.application - ERROR - Exception in callback functools.partial(<bound method IOLoop._discard_future_result of <zmq.eventloop.ioloop.ZMQIOLoop object at 0x7fb5a03a0880>>, <Task finished name='Task-2092134' coro=<DaskDistributedBackend.apply_async.<locals>.f() done, defined at /gpfs/commons/home/jsingh/.conda/envs/spatial/lib/python3.9/site-packages/joblib/_dask.py:323> exception=TypeError('Delayed objects of unspecified length are not iterable')>)\n",
      "Traceback (most recent call last):\n",
      "  File \"/gpfs/commons/home/jsingh/.conda/envs/spatial/lib/python3.9/site-packages/tornado/ioloop.py\", line 741, in _run_callback\n",
      "    ret = callback()\n",
      "  File \"/gpfs/commons/home/jsingh/.conda/envs/spatial/lib/python3.9/site-packages/tornado/ioloop.py\", line 765, in _discard_future_result\n",
      "    future.result()\n",
      "  File \"/gpfs/commons/home/jsingh/.conda/envs/spatial/lib/python3.9/site-packages/joblib/_dask.py\", line 324, in f\n",
      "    batch, tasks = await self._to_func_args(func)\n",
      "  File \"/gpfs/commons/home/jsingh/.conda/envs/spatial/lib/python3.9/site-packages/joblib/_dask.py\", line 310, in _to_func_args\n",
      "    for f, args, kwargs in func.items:\n",
      "  File \"/gpfs/commons/home/jsingh/.conda/envs/spatial/lib/python3.9/site-packages/dask/delayed.py\", line 581, in __iter__\n",
      "    raise TypeError(\"Delayed objects of unspecified length are not iterable\")\n",
      "TypeError: Delayed objects of unspecified length are not iterable\n",
      "2022-06-22 23:50:17,960 - tornado.application - ERROR - Exception in callback functools.partial(<bound method IOLoop._discard_future_result of <zmq.eventloop.ioloop.ZMQIOLoop object at 0x7fb5a03a0880>>, <Task finished name='Task-2092135' coro=<DaskDistributedBackend.apply_async.<locals>.f() done, defined at /gpfs/commons/home/jsingh/.conda/envs/spatial/lib/python3.9/site-packages/joblib/_dask.py:323> exception=TypeError('Delayed objects of unspecified length are not iterable')>)\n",
      "Traceback (most recent call last):\n",
      "  File \"/gpfs/commons/home/jsingh/.conda/envs/spatial/lib/python3.9/site-packages/tornado/ioloop.py\", line 741, in _run_callback\n",
      "    ret = callback()\n",
      "  File \"/gpfs/commons/home/jsingh/.conda/envs/spatial/lib/python3.9/site-packages/tornado/ioloop.py\", line 765, in _discard_future_result\n",
      "    future.result()\n",
      "  File \"/gpfs/commons/home/jsingh/.conda/envs/spatial/lib/python3.9/site-packages/joblib/_dask.py\", line 324, in f\n",
      "    batch, tasks = await self._to_func_args(func)\n",
      "  File \"/gpfs/commons/home/jsingh/.conda/envs/spatial/lib/python3.9/site-packages/joblib/_dask.py\", line 310, in _to_func_args\n",
      "    for f, args, kwargs in func.items:\n",
      "  File \"/gpfs/commons/home/jsingh/.conda/envs/spatial/lib/python3.9/site-packages/dask/delayed.py\", line 581, in __iter__\n",
      "    raise TypeError(\"Delayed objects of unspecified length are not iterable\")\n",
      "TypeError: Delayed objects of unspecified length are not iterable\n",
      "2022-06-22 23:50:17,961 - tornado.application - ERROR - Exception in callback functools.partial(<bound method IOLoop._discard_future_result of <zmq.eventloop.ioloop.ZMQIOLoop object at 0x7fb5a03a0880>>, <Task finished name='Task-2092136' coro=<DaskDistributedBackend.apply_async.<locals>.f() done, defined at /gpfs/commons/home/jsingh/.conda/envs/spatial/lib/python3.9/site-packages/joblib/_dask.py:323> exception=TypeError('Delayed objects of unspecified length are not iterable')>)\n",
      "Traceback (most recent call last):\n",
      "  File \"/gpfs/commons/home/jsingh/.conda/envs/spatial/lib/python3.9/site-packages/tornado/ioloop.py\", line 741, in _run_callback\n",
      "    ret = callback()\n",
      "  File \"/gpfs/commons/home/jsingh/.conda/envs/spatial/lib/python3.9/site-packages/tornado/ioloop.py\", line 765, in _discard_future_result\n",
      "    future.result()\n",
      "  File \"/gpfs/commons/home/jsingh/.conda/envs/spatial/lib/python3.9/site-packages/joblib/_dask.py\", line 324, in f\n",
      "    batch, tasks = await self._to_func_args(func)\n",
      "  File \"/gpfs/commons/home/jsingh/.conda/envs/spatial/lib/python3.9/site-packages/joblib/_dask.py\", line 310, in _to_func_args\n",
      "    for f, args, kwargs in func.items:\n",
      "  File \"/gpfs/commons/home/jsingh/.conda/envs/spatial/lib/python3.9/site-packages/dask/delayed.py\", line 581, in __iter__\n",
      "    raise TypeError(\"Delayed objects of unspecified length are not iterable\")\n",
      "TypeError: Delayed objects of unspecified length are not iterable\n",
      "2022-06-22 23:50:17,962 - tornado.application - ERROR - Exception in callback functools.partial(<bound method IOLoop._discard_future_result of <zmq.eventloop.ioloop.ZMQIOLoop object at 0x7fb5a03a0880>>, <Task finished name='Task-2092137' coro=<DaskDistributedBackend.apply_async.<locals>.f() done, defined at /gpfs/commons/home/jsingh/.conda/envs/spatial/lib/python3.9/site-packages/joblib/_dask.py:323> exception=TypeError('Delayed objects of unspecified length are not iterable')>)\n",
      "Traceback (most recent call last):\n",
      "  File \"/gpfs/commons/home/jsingh/.conda/envs/spatial/lib/python3.9/site-packages/tornado/ioloop.py\", line 741, in _run_callback\n",
      "    ret = callback()\n",
      "  File \"/gpfs/commons/home/jsingh/.conda/envs/spatial/lib/python3.9/site-packages/tornado/ioloop.py\", line 765, in _discard_future_result\n",
      "    future.result()\n",
      "  File \"/gpfs/commons/home/jsingh/.conda/envs/spatial/lib/python3.9/site-packages/joblib/_dask.py\", line 324, in f\n",
      "    batch, tasks = await self._to_func_args(func)\n",
      "  File \"/gpfs/commons/home/jsingh/.conda/envs/spatial/lib/python3.9/site-packages/joblib/_dask.py\", line 310, in _to_func_args\n",
      "    for f, args, kwargs in func.items:\n",
      "  File \"/gpfs/commons/home/jsingh/.conda/envs/spatial/lib/python3.9/site-packages/dask/delayed.py\", line 581, in __iter__\n",
      "    raise TypeError(\"Delayed objects of unspecified length are not iterable\")\n",
      "TypeError: Delayed objects of unspecified length are not iterable\n"
     ]
    },
    {
     "name": "stderr",
     "output_type": "stream",
     "text": [
      "2022-06-22 23:50:17,963 - tornado.application - ERROR - Exception in callback functools.partial(<bound method IOLoop._discard_future_result of <zmq.eventloop.ioloop.ZMQIOLoop object at 0x7fb5a03a0880>>, <Task finished name='Task-2092138' coro=<DaskDistributedBackend.apply_async.<locals>.f() done, defined at /gpfs/commons/home/jsingh/.conda/envs/spatial/lib/python3.9/site-packages/joblib/_dask.py:323> exception=TypeError('Delayed objects of unspecified length are not iterable')>)\n",
      "Traceback (most recent call last):\n",
      "  File \"/gpfs/commons/home/jsingh/.conda/envs/spatial/lib/python3.9/site-packages/tornado/ioloop.py\", line 741, in _run_callback\n",
      "    ret = callback()\n",
      "  File \"/gpfs/commons/home/jsingh/.conda/envs/spatial/lib/python3.9/site-packages/tornado/ioloop.py\", line 765, in _discard_future_result\n",
      "    future.result()\n",
      "  File \"/gpfs/commons/home/jsingh/.conda/envs/spatial/lib/python3.9/site-packages/joblib/_dask.py\", line 324, in f\n",
      "    batch, tasks = await self._to_func_args(func)\n",
      "  File \"/gpfs/commons/home/jsingh/.conda/envs/spatial/lib/python3.9/site-packages/joblib/_dask.py\", line 310, in _to_func_args\n",
      "    for f, args, kwargs in func.items:\n",
      "  File \"/gpfs/commons/home/jsingh/.conda/envs/spatial/lib/python3.9/site-packages/dask/delayed.py\", line 581, in __iter__\n",
      "    raise TypeError(\"Delayed objects of unspecified length are not iterable\")\n",
      "TypeError: Delayed objects of unspecified length are not iterable\n",
      "2022-06-22 23:50:17,964 - tornado.application - ERROR - Exception in callback functools.partial(<bound method IOLoop._discard_future_result of <zmq.eventloop.ioloop.ZMQIOLoop object at 0x7fb5a03a0880>>, <Task finished name='Task-2092139' coro=<DaskDistributedBackend.apply_async.<locals>.f() done, defined at /gpfs/commons/home/jsingh/.conda/envs/spatial/lib/python3.9/site-packages/joblib/_dask.py:323> exception=TypeError('Delayed objects of unspecified length are not iterable')>)\n",
      "Traceback (most recent call last):\n",
      "  File \"/gpfs/commons/home/jsingh/.conda/envs/spatial/lib/python3.9/site-packages/tornado/ioloop.py\", line 741, in _run_callback\n",
      "    ret = callback()\n",
      "  File \"/gpfs/commons/home/jsingh/.conda/envs/spatial/lib/python3.9/site-packages/tornado/ioloop.py\", line 765, in _discard_future_result\n",
      "    future.result()\n",
      "  File \"/gpfs/commons/home/jsingh/.conda/envs/spatial/lib/python3.9/site-packages/joblib/_dask.py\", line 324, in f\n",
      "    batch, tasks = await self._to_func_args(func)\n",
      "  File \"/gpfs/commons/home/jsingh/.conda/envs/spatial/lib/python3.9/site-packages/joblib/_dask.py\", line 310, in _to_func_args\n",
      "    for f, args, kwargs in func.items:\n",
      "  File \"/gpfs/commons/home/jsingh/.conda/envs/spatial/lib/python3.9/site-packages/dask/delayed.py\", line 581, in __iter__\n",
      "    raise TypeError(\"Delayed objects of unspecified length are not iterable\")\n",
      "TypeError: Delayed objects of unspecified length are not iterable\n",
      "2022-06-22 23:50:17,965 - tornado.application - ERROR - Exception in callback functools.partial(<bound method IOLoop._discard_future_result of <zmq.eventloop.ioloop.ZMQIOLoop object at 0x7fb5a03a0880>>, <Task finished name='Task-2092140' coro=<DaskDistributedBackend.apply_async.<locals>.f() done, defined at /gpfs/commons/home/jsingh/.conda/envs/spatial/lib/python3.9/site-packages/joblib/_dask.py:323> exception=TypeError('Delayed objects of unspecified length are not iterable')>)\n",
      "Traceback (most recent call last):\n",
      "  File \"/gpfs/commons/home/jsingh/.conda/envs/spatial/lib/python3.9/site-packages/tornado/ioloop.py\", line 741, in _run_callback\n",
      "    ret = callback()\n",
      "  File \"/gpfs/commons/home/jsingh/.conda/envs/spatial/lib/python3.9/site-packages/tornado/ioloop.py\", line 765, in _discard_future_result\n",
      "    future.result()\n",
      "  File \"/gpfs/commons/home/jsingh/.conda/envs/spatial/lib/python3.9/site-packages/joblib/_dask.py\", line 324, in f\n",
      "    batch, tasks = await self._to_func_args(func)\n",
      "  File \"/gpfs/commons/home/jsingh/.conda/envs/spatial/lib/python3.9/site-packages/joblib/_dask.py\", line 310, in _to_func_args\n",
      "    for f, args, kwargs in func.items:\n",
      "  File \"/gpfs/commons/home/jsingh/.conda/envs/spatial/lib/python3.9/site-packages/dask/delayed.py\", line 581, in __iter__\n",
      "    raise TypeError(\"Delayed objects of unspecified length are not iterable\")\n",
      "TypeError: Delayed objects of unspecified length are not iterable\n",
      "2022-06-22 23:50:17,966 - tornado.application - ERROR - Exception in callback functools.partial(<bound method IOLoop._discard_future_result of <zmq.eventloop.ioloop.ZMQIOLoop object at 0x7fb5a03a0880>>, <Task finished name='Task-2092141' coro=<DaskDistributedBackend.apply_async.<locals>.f() done, defined at /gpfs/commons/home/jsingh/.conda/envs/spatial/lib/python3.9/site-packages/joblib/_dask.py:323> exception=TypeError('Delayed objects of unspecified length are not iterable')>)\n",
      "Traceback (most recent call last):\n",
      "  File \"/gpfs/commons/home/jsingh/.conda/envs/spatial/lib/python3.9/site-packages/tornado/ioloop.py\", line 741, in _run_callback\n",
      "    ret = callback()\n",
      "  File \"/gpfs/commons/home/jsingh/.conda/envs/spatial/lib/python3.9/site-packages/tornado/ioloop.py\", line 765, in _discard_future_result\n",
      "    future.result()\n",
      "  File \"/gpfs/commons/home/jsingh/.conda/envs/spatial/lib/python3.9/site-packages/joblib/_dask.py\", line 324, in f\n",
      "    batch, tasks = await self._to_func_args(func)\n",
      "  File \"/gpfs/commons/home/jsingh/.conda/envs/spatial/lib/python3.9/site-packages/joblib/_dask.py\", line 310, in _to_func_args\n",
      "    for f, args, kwargs in func.items:\n",
      "  File \"/gpfs/commons/home/jsingh/.conda/envs/spatial/lib/python3.9/site-packages/dask/delayed.py\", line 581, in __iter__\n",
      "    raise TypeError(\"Delayed objects of unspecified length are not iterable\")\n",
      "TypeError: Delayed objects of unspecified length are not iterable\n",
      "2022-06-22 23:50:17,968 - tornado.application - ERROR - Exception in callback functools.partial(<bound method IOLoop._discard_future_result of <zmq.eventloop.ioloop.ZMQIOLoop object at 0x7fb5a03a0880>>, <Task finished name='Task-2092142' coro=<DaskDistributedBackend.apply_async.<locals>.f() done, defined at /gpfs/commons/home/jsingh/.conda/envs/spatial/lib/python3.9/site-packages/joblib/_dask.py:323> exception=TypeError('Delayed objects of unspecified length are not iterable')>)\n",
      "Traceback (most recent call last):\n",
      "  File \"/gpfs/commons/home/jsingh/.conda/envs/spatial/lib/python3.9/site-packages/tornado/ioloop.py\", line 741, in _run_callback\n",
      "    ret = callback()\n",
      "  File \"/gpfs/commons/home/jsingh/.conda/envs/spatial/lib/python3.9/site-packages/tornado/ioloop.py\", line 765, in _discard_future_result\n",
      "    future.result()\n",
      "  File \"/gpfs/commons/home/jsingh/.conda/envs/spatial/lib/python3.9/site-packages/joblib/_dask.py\", line 324, in f\n",
      "    batch, tasks = await self._to_func_args(func)\n",
      "  File \"/gpfs/commons/home/jsingh/.conda/envs/spatial/lib/python3.9/site-packages/joblib/_dask.py\", line 310, in _to_func_args\n",
      "    for f, args, kwargs in func.items:\n",
      "  File \"/gpfs/commons/home/jsingh/.conda/envs/spatial/lib/python3.9/site-packages/dask/delayed.py\", line 581, in __iter__\n",
      "    raise TypeError(\"Delayed objects of unspecified length are not iterable\")\n",
      "TypeError: Delayed objects of unspecified length are not iterable\n",
      "2022-06-22 23:50:17,969 - tornado.application - ERROR - Exception in callback functools.partial(<bound method IOLoop._discard_future_result of <zmq.eventloop.ioloop.ZMQIOLoop object at 0x7fb5a03a0880>>, <Task finished name='Task-2092143' coro=<DaskDistributedBackend.apply_async.<locals>.f() done, defined at /gpfs/commons/home/jsingh/.conda/envs/spatial/lib/python3.9/site-packages/joblib/_dask.py:323> exception=TypeError('Delayed objects of unspecified length are not iterable')>)\n",
      "Traceback (most recent call last):\n",
      "  File \"/gpfs/commons/home/jsingh/.conda/envs/spatial/lib/python3.9/site-packages/tornado/ioloop.py\", line 741, in _run_callback\n",
      "    ret = callback()\n",
      "  File \"/gpfs/commons/home/jsingh/.conda/envs/spatial/lib/python3.9/site-packages/tornado/ioloop.py\", line 765, in _discard_future_result\n",
      "    future.result()\n",
      "  File \"/gpfs/commons/home/jsingh/.conda/envs/spatial/lib/python3.9/site-packages/joblib/_dask.py\", line 324, in f\n",
      "    batch, tasks = await self._to_func_args(func)\n",
      "  File \"/gpfs/commons/home/jsingh/.conda/envs/spatial/lib/python3.9/site-packages/joblib/_dask.py\", line 310, in _to_func_args\n",
      "    for f, args, kwargs in func.items:\n",
      "  File \"/gpfs/commons/home/jsingh/.conda/envs/spatial/lib/python3.9/site-packages/dask/delayed.py\", line 581, in __iter__\n",
      "    raise TypeError(\"Delayed objects of unspecified length are not iterable\")\n",
      "TypeError: Delayed objects of unspecified length are not iterable\n"
     ]
    },
    {
     "name": "stderr",
     "output_type": "stream",
     "text": [
      "2022-06-22 23:50:17,970 - tornado.application - ERROR - Exception in callback functools.partial(<bound method IOLoop._discard_future_result of <zmq.eventloop.ioloop.ZMQIOLoop object at 0x7fb5a03a0880>>, <Task finished name='Task-2092144' coro=<DaskDistributedBackend.apply_async.<locals>.f() done, defined at /gpfs/commons/home/jsingh/.conda/envs/spatial/lib/python3.9/site-packages/joblib/_dask.py:323> exception=TypeError('Delayed objects of unspecified length are not iterable')>)\n",
      "Traceback (most recent call last):\n",
      "  File \"/gpfs/commons/home/jsingh/.conda/envs/spatial/lib/python3.9/site-packages/tornado/ioloop.py\", line 741, in _run_callback\n",
      "    ret = callback()\n",
      "  File \"/gpfs/commons/home/jsingh/.conda/envs/spatial/lib/python3.9/site-packages/tornado/ioloop.py\", line 765, in _discard_future_result\n",
      "    future.result()\n",
      "  File \"/gpfs/commons/home/jsingh/.conda/envs/spatial/lib/python3.9/site-packages/joblib/_dask.py\", line 324, in f\n",
      "    batch, tasks = await self._to_func_args(func)\n",
      "  File \"/gpfs/commons/home/jsingh/.conda/envs/spatial/lib/python3.9/site-packages/joblib/_dask.py\", line 310, in _to_func_args\n",
      "    for f, args, kwargs in func.items:\n",
      "  File \"/gpfs/commons/home/jsingh/.conda/envs/spatial/lib/python3.9/site-packages/dask/delayed.py\", line 581, in __iter__\n",
      "    raise TypeError(\"Delayed objects of unspecified length are not iterable\")\n",
      "TypeError: Delayed objects of unspecified length are not iterable\n",
      "2022-06-22 23:50:17,971 - tornado.application - ERROR - Exception in callback functools.partial(<bound method IOLoop._discard_future_result of <zmq.eventloop.ioloop.ZMQIOLoop object at 0x7fb5a03a0880>>, <Task finished name='Task-2092145' coro=<DaskDistributedBackend.apply_async.<locals>.f() done, defined at /gpfs/commons/home/jsingh/.conda/envs/spatial/lib/python3.9/site-packages/joblib/_dask.py:323> exception=TypeError('Delayed objects of unspecified length are not iterable')>)\n",
      "Traceback (most recent call last):\n",
      "  File \"/gpfs/commons/home/jsingh/.conda/envs/spatial/lib/python3.9/site-packages/tornado/ioloop.py\", line 741, in _run_callback\n",
      "    ret = callback()\n",
      "  File \"/gpfs/commons/home/jsingh/.conda/envs/spatial/lib/python3.9/site-packages/tornado/ioloop.py\", line 765, in _discard_future_result\n",
      "    future.result()\n",
      "  File \"/gpfs/commons/home/jsingh/.conda/envs/spatial/lib/python3.9/site-packages/joblib/_dask.py\", line 324, in f\n",
      "    batch, tasks = await self._to_func_args(func)\n",
      "  File \"/gpfs/commons/home/jsingh/.conda/envs/spatial/lib/python3.9/site-packages/joblib/_dask.py\", line 310, in _to_func_args\n",
      "    for f, args, kwargs in func.items:\n",
      "  File \"/gpfs/commons/home/jsingh/.conda/envs/spatial/lib/python3.9/site-packages/dask/delayed.py\", line 581, in __iter__\n",
      "    raise TypeError(\"Delayed objects of unspecified length are not iterable\")\n",
      "TypeError: Delayed objects of unspecified length are not iterable\n",
      "2022-06-22 23:50:17,973 - tornado.application - ERROR - Exception in callback functools.partial(<bound method IOLoop._discard_future_result of <zmq.eventloop.ioloop.ZMQIOLoop object at 0x7fb5a03a0880>>, <Task finished name='Task-2092146' coro=<DaskDistributedBackend.apply_async.<locals>.f() done, defined at /gpfs/commons/home/jsingh/.conda/envs/spatial/lib/python3.9/site-packages/joblib/_dask.py:323> exception=TypeError('Delayed objects of unspecified length are not iterable')>)\n",
      "Traceback (most recent call last):\n",
      "  File \"/gpfs/commons/home/jsingh/.conda/envs/spatial/lib/python3.9/site-packages/tornado/ioloop.py\", line 741, in _run_callback\n",
      "    ret = callback()\n",
      "  File \"/gpfs/commons/home/jsingh/.conda/envs/spatial/lib/python3.9/site-packages/tornado/ioloop.py\", line 765, in _discard_future_result\n",
      "    future.result()\n",
      "  File \"/gpfs/commons/home/jsingh/.conda/envs/spatial/lib/python3.9/site-packages/joblib/_dask.py\", line 324, in f\n",
      "    batch, tasks = await self._to_func_args(func)\n",
      "  File \"/gpfs/commons/home/jsingh/.conda/envs/spatial/lib/python3.9/site-packages/joblib/_dask.py\", line 310, in _to_func_args\n",
      "    for f, args, kwargs in func.items:\n",
      "  File \"/gpfs/commons/home/jsingh/.conda/envs/spatial/lib/python3.9/site-packages/dask/delayed.py\", line 581, in __iter__\n",
      "    raise TypeError(\"Delayed objects of unspecified length are not iterable\")\n",
      "TypeError: Delayed objects of unspecified length are not iterable\n",
      "2022-06-22 23:50:17,974 - tornado.application - ERROR - Exception in callback functools.partial(<bound method IOLoop._discard_future_result of <zmq.eventloop.ioloop.ZMQIOLoop object at 0x7fb5a03a0880>>, <Task finished name='Task-2092147' coro=<DaskDistributedBackend.apply_async.<locals>.f() done, defined at /gpfs/commons/home/jsingh/.conda/envs/spatial/lib/python3.9/site-packages/joblib/_dask.py:323> exception=TypeError('Delayed objects of unspecified length are not iterable')>)\n",
      "Traceback (most recent call last):\n",
      "  File \"/gpfs/commons/home/jsingh/.conda/envs/spatial/lib/python3.9/site-packages/tornado/ioloop.py\", line 741, in _run_callback\n",
      "    ret = callback()\n",
      "  File \"/gpfs/commons/home/jsingh/.conda/envs/spatial/lib/python3.9/site-packages/tornado/ioloop.py\", line 765, in _discard_future_result\n",
      "    future.result()\n",
      "  File \"/gpfs/commons/home/jsingh/.conda/envs/spatial/lib/python3.9/site-packages/joblib/_dask.py\", line 324, in f\n",
      "    batch, tasks = await self._to_func_args(func)\n",
      "  File \"/gpfs/commons/home/jsingh/.conda/envs/spatial/lib/python3.9/site-packages/joblib/_dask.py\", line 310, in _to_func_args\n",
      "    for f, args, kwargs in func.items:\n",
      "  File \"/gpfs/commons/home/jsingh/.conda/envs/spatial/lib/python3.9/site-packages/dask/delayed.py\", line 581, in __iter__\n",
      "    raise TypeError(\"Delayed objects of unspecified length are not iterable\")\n",
      "TypeError: Delayed objects of unspecified length are not iterable\n",
      "2022-06-22 23:50:17,975 - tornado.application - ERROR - Exception in callback functools.partial(<bound method IOLoop._discard_future_result of <zmq.eventloop.ioloop.ZMQIOLoop object at 0x7fb5a03a0880>>, <Task finished name='Task-2092148' coro=<DaskDistributedBackend.apply_async.<locals>.f() done, defined at /gpfs/commons/home/jsingh/.conda/envs/spatial/lib/python3.9/site-packages/joblib/_dask.py:323> exception=TypeError('Delayed objects of unspecified length are not iterable')>)\n",
      "Traceback (most recent call last):\n",
      "  File \"/gpfs/commons/home/jsingh/.conda/envs/spatial/lib/python3.9/site-packages/tornado/ioloop.py\", line 741, in _run_callback\n",
      "    ret = callback()\n",
      "  File \"/gpfs/commons/home/jsingh/.conda/envs/spatial/lib/python3.9/site-packages/tornado/ioloop.py\", line 765, in _discard_future_result\n",
      "    future.result()\n",
      "  File \"/gpfs/commons/home/jsingh/.conda/envs/spatial/lib/python3.9/site-packages/joblib/_dask.py\", line 324, in f\n",
      "    batch, tasks = await self._to_func_args(func)\n",
      "  File \"/gpfs/commons/home/jsingh/.conda/envs/spatial/lib/python3.9/site-packages/joblib/_dask.py\", line 310, in _to_func_args\n",
      "    for f, args, kwargs in func.items:\n",
      "  File \"/gpfs/commons/home/jsingh/.conda/envs/spatial/lib/python3.9/site-packages/dask/delayed.py\", line 581, in __iter__\n",
      "    raise TypeError(\"Delayed objects of unspecified length are not iterable\")\n",
      "TypeError: Delayed objects of unspecified length are not iterable\n",
      "2022-06-22 23:50:17,976 - tornado.application - ERROR - Exception in callback functools.partial(<bound method IOLoop._discard_future_result of <zmq.eventloop.ioloop.ZMQIOLoop object at 0x7fb5a03a0880>>, <Task finished name='Task-2092149' coro=<DaskDistributedBackend.apply_async.<locals>.f() done, defined at /gpfs/commons/home/jsingh/.conda/envs/spatial/lib/python3.9/site-packages/joblib/_dask.py:323> exception=TypeError('Delayed objects of unspecified length are not iterable')>)\n",
      "Traceback (most recent call last):\n",
      "  File \"/gpfs/commons/home/jsingh/.conda/envs/spatial/lib/python3.9/site-packages/tornado/ioloop.py\", line 741, in _run_callback\n",
      "    ret = callback()\n",
      "  File \"/gpfs/commons/home/jsingh/.conda/envs/spatial/lib/python3.9/site-packages/tornado/ioloop.py\", line 765, in _discard_future_result\n",
      "    future.result()\n",
      "  File \"/gpfs/commons/home/jsingh/.conda/envs/spatial/lib/python3.9/site-packages/joblib/_dask.py\", line 324, in f\n",
      "    batch, tasks = await self._to_func_args(func)\n",
      "  File \"/gpfs/commons/home/jsingh/.conda/envs/spatial/lib/python3.9/site-packages/joblib/_dask.py\", line 310, in _to_func_args\n",
      "    for f, args, kwargs in func.items:\n",
      "  File \"/gpfs/commons/home/jsingh/.conda/envs/spatial/lib/python3.9/site-packages/dask/delayed.py\", line 581, in __iter__\n",
      "    raise TypeError(\"Delayed objects of unspecified length are not iterable\")\n",
      "TypeError: Delayed objects of unspecified length are not iterable\n"
     ]
    },
    {
     "name": "stderr",
     "output_type": "stream",
     "text": [
      "2022-06-22 23:53:36,009 - bokeh.core.property.validation - ERROR - 'str' object has no attribute 'text'\n",
      "Traceback (most recent call last):\n",
      "  File \"/gpfs/commons/home/jsingh/.conda/envs/spatial/lib/python3.9/site-packages/distributed/utils.py\", line 767, in wrapper\n",
      "    return func(*args, **kwargs)\n",
      "  File \"/gpfs/commons/home/jsingh/.conda/envs/spatial/lib/python3.9/site-packages/distributed/dashboard/components/scheduler.py\", line 355, in update\n",
      "    self.root.title.text = title\n",
      "AttributeError: 'str' object has no attribute 'text'\n",
      "2022-06-22 23:53:36,012 - bokeh.application.handlers.function - ERROR - 'str' object has no attribute 'text'\n",
      "Traceback (most recent call last):\n",
      "  File \"/gpfs/commons/home/jsingh/.conda/envs/spatial/lib/python3.9/site-packages/distributed/utils.py\", line 767, in wrapper\n",
      "    return func(*args, **kwargs)\n",
      "  File \"/gpfs/commons/home/jsingh/.conda/envs/spatial/lib/python3.9/site-packages/distributed/dashboard/components/scheduler.py\", line 3915, in status_doc\n",
      "    cluster_memory.update()\n",
      "  File \"/gpfs/commons/home/jsingh/.conda/envs/spatial/lib/python3.9/site-packages/bokeh/core/property/validation.py\", line 95, in func\n",
      "    return input_function(*args, **kwargs)\n",
      "  File \"/gpfs/commons/home/jsingh/.conda/envs/spatial/lib/python3.9/site-packages/distributed/utils.py\", line 767, in wrapper\n",
      "    return func(*args, **kwargs)\n",
      "  File \"/gpfs/commons/home/jsingh/.conda/envs/spatial/lib/python3.9/site-packages/distributed/dashboard/components/scheduler.py\", line 355, in update\n",
      "    self.root.title.text = title\n",
      "AttributeError: 'str' object has no attribute 'text'\n",
      "2022-06-22 23:53:36,013 - tornado.application - ERROR - Uncaught exception GET /status (192.168.101.162)\n",
      "HTTPServerRequest(protocol='http', host='10.4.202.10:8787', method='GET', uri='/status', version='HTTP/1.1', remote_ip='192.168.101.162')\n",
      "Traceback (most recent call last):\n",
      "  File \"/gpfs/commons/home/jsingh/.conda/envs/spatial/lib/python3.9/site-packages/tornado/web.py\", line 1704, in _execute\n",
      "    result = await result\n",
      "  File \"/gpfs/commons/home/jsingh/.conda/envs/spatial/lib/python3.9/site-packages/bokeh/server/views/doc_handler.py\", line 54, in get\n",
      "    session = await self.get_session()\n",
      "  File \"/gpfs/commons/home/jsingh/.conda/envs/spatial/lib/python3.9/site-packages/bokeh/server/views/session_handler.py\", line 144, in get_session\n",
      "    session = await self.application_context.create_session_if_needed(session_id, self.request, token)\n",
      "  File \"/gpfs/commons/home/jsingh/.conda/envs/spatial/lib/python3.9/site-packages/bokeh/server/contexts.py\", line 243, in create_session_if_needed\n",
      "    self._application.initialize_document(doc)\n",
      "  File \"/gpfs/commons/home/jsingh/.conda/envs/spatial/lib/python3.9/site-packages/bokeh/application/application.py\", line 194, in initialize_document\n",
      "    h.modify_document(doc)\n",
      "  File \"/gpfs/commons/home/jsingh/.conda/envs/spatial/lib/python3.9/site-packages/bokeh/application/handlers/function.py\", line 143, in modify_document\n",
      "    self._func(doc)\n",
      "  File \"/gpfs/commons/home/jsingh/.conda/envs/spatial/lib/python3.9/site-packages/distributed/utils.py\", line 767, in wrapper\n",
      "    return func(*args, **kwargs)\n",
      "  File \"/gpfs/commons/home/jsingh/.conda/envs/spatial/lib/python3.9/site-packages/distributed/dashboard/components/scheduler.py\", line 3915, in status_doc\n",
      "    cluster_memory.update()\n",
      "  File \"/gpfs/commons/home/jsingh/.conda/envs/spatial/lib/python3.9/site-packages/bokeh/core/property/validation.py\", line 95, in func\n",
      "    return input_function(*args, **kwargs)\n",
      "  File \"/gpfs/commons/home/jsingh/.conda/envs/spatial/lib/python3.9/site-packages/distributed/utils.py\", line 767, in wrapper\n",
      "    return func(*args, **kwargs)\n",
      "  File \"/gpfs/commons/home/jsingh/.conda/envs/spatial/lib/python3.9/site-packages/distributed/dashboard/components/scheduler.py\", line 355, in update\n",
      "    self.root.title.text = title\n",
      "AttributeError: 'str' object has no attribute 'text'\n",
      "2022-06-22 23:53:48,732 - bokeh.core.property.validation - ERROR - 'str' object has no attribute 'text'\n",
      "Traceback (most recent call last):\n",
      "  File \"/gpfs/commons/home/jsingh/.conda/envs/spatial/lib/python3.9/site-packages/distributed/utils.py\", line 767, in wrapper\n",
      "    return func(*args, **kwargs)\n",
      "  File \"/gpfs/commons/home/jsingh/.conda/envs/spatial/lib/python3.9/site-packages/distributed/dashboard/components/scheduler.py\", line 355, in update\n",
      "    self.root.title.text = title\n",
      "AttributeError: 'str' object has no attribute 'text'\n",
      "2022-06-22 23:53:48,737 - bokeh.application.handlers.function - ERROR - 'str' object has no attribute 'text'\n",
      "Traceback (most recent call last):\n",
      "  File \"/gpfs/commons/home/jsingh/.conda/envs/spatial/lib/python3.9/site-packages/distributed/utils.py\", line 767, in wrapper\n",
      "    return func(*args, **kwargs)\n",
      "  File \"/gpfs/commons/home/jsingh/.conda/envs/spatial/lib/python3.9/site-packages/distributed/dashboard/components/scheduler.py\", line 3915, in status_doc\n",
      "    cluster_memory.update()\n",
      "  File \"/gpfs/commons/home/jsingh/.conda/envs/spatial/lib/python3.9/site-packages/bokeh/core/property/validation.py\", line 95, in func\n",
      "    return input_function(*args, **kwargs)\n",
      "  File \"/gpfs/commons/home/jsingh/.conda/envs/spatial/lib/python3.9/site-packages/distributed/utils.py\", line 767, in wrapper\n",
      "    return func(*args, **kwargs)\n",
      "  File \"/gpfs/commons/home/jsingh/.conda/envs/spatial/lib/python3.9/site-packages/distributed/dashboard/components/scheduler.py\", line 355, in update\n",
      "    self.root.title.text = title\n",
      "AttributeError: 'str' object has no attribute 'text'\n",
      "2022-06-22 23:53:48,739 - tornado.application - ERROR - Uncaught exception GET /status (192.168.101.162)\n",
      "HTTPServerRequest(protocol='http', host='10.4.202.10:8787', method='GET', uri='/status', version='HTTP/1.1', remote_ip='192.168.101.162')\n",
      "Traceback (most recent call last):\n",
      "  File \"/gpfs/commons/home/jsingh/.conda/envs/spatial/lib/python3.9/site-packages/tornado/web.py\", line 1704, in _execute\n",
      "    result = await result\n",
      "  File \"/gpfs/commons/home/jsingh/.conda/envs/spatial/lib/python3.9/site-packages/bokeh/server/views/doc_handler.py\", line 54, in get\n",
      "    session = await self.get_session()\n",
      "  File \"/gpfs/commons/home/jsingh/.conda/envs/spatial/lib/python3.9/site-packages/bokeh/server/views/session_handler.py\", line 144, in get_session\n",
      "    session = await self.application_context.create_session_if_needed(session_id, self.request, token)\n",
      "  File \"/gpfs/commons/home/jsingh/.conda/envs/spatial/lib/python3.9/site-packages/bokeh/server/contexts.py\", line 243, in create_session_if_needed\n",
      "    self._application.initialize_document(doc)\n",
      "  File \"/gpfs/commons/home/jsingh/.conda/envs/spatial/lib/python3.9/site-packages/bokeh/application/application.py\", line 194, in initialize_document\n",
      "    h.modify_document(doc)\n",
      "  File \"/gpfs/commons/home/jsingh/.conda/envs/spatial/lib/python3.9/site-packages/bokeh/application/handlers/function.py\", line 143, in modify_document\n",
      "    self._func(doc)\n",
      "  File \"/gpfs/commons/home/jsingh/.conda/envs/spatial/lib/python3.9/site-packages/distributed/utils.py\", line 767, in wrapper\n",
      "    return func(*args, **kwargs)\n",
      "  File \"/gpfs/commons/home/jsingh/.conda/envs/spatial/lib/python3.9/site-packages/distributed/dashboard/components/scheduler.py\", line 3915, in status_doc\n",
      "    cluster_memory.update()\n",
      "  File \"/gpfs/commons/home/jsingh/.conda/envs/spatial/lib/python3.9/site-packages/bokeh/core/property/validation.py\", line 95, in func\n",
      "    return input_function(*args, **kwargs)\n",
      "  File \"/gpfs/commons/home/jsingh/.conda/envs/spatial/lib/python3.9/site-packages/distributed/utils.py\", line 767, in wrapper\n",
      "    return func(*args, **kwargs)\n",
      "  File \"/gpfs/commons/home/jsingh/.conda/envs/spatial/lib/python3.9/site-packages/distributed/dashboard/components/scheduler.py\", line 355, in update\n",
      "    self.root.title.text = title\n",
      "AttributeError: 'str' object has no attribute 'text'\n",
      "\n",
      "KeyboardInterrupt\n",
      "\n"
     ]
    }
   ],
   "source": [
    "#Way 5 using joblib \n",
    "def get_pixels(lab):\n",
    "    m = dask.array.ma.masked_array(dk,np.squeeze([labels == lab]))\n",
    "    mv = dask.array.mean(m)\n",
    "    return mv\n",
    "\n",
    "with parallel_backend('dask',scheduler_host=cluster.scheduler._address):\n",
    "    results = Parallel(n_jobs=-1)(delayed(get_pixels)(lab) for lab in range(100))\n",
    "\n",
    "\n",
    "\n",
    "\n",
    "\n"
   ]
  },
  {
   "cell_type": "code",
   "execution_count": 24,
   "metadata": {},
   "outputs": [],
   "source": [
    "#Way x : Dask image functions\n",
    "import dask_image\n",
    "\n",
    "index = list(range(11232))\n",
    "del index[0]\n",
    "\n",
    "ar = dask_image.ndmeasure.labeled_comprehension(image = plane, \n",
    "                                                label_image = labels, index = index, func = dask_image.ndmeasure.mean,\n",
    "                                                out_dtype = float, default = None, pass_positions = False)\n",
    "v = ar.compute()"
   ]
  },
  {
   "cell_type": "code",
   "execution_count": null,
   "metadata": {},
   "outputs": [],
   "source": [
    "#ADJUSTING TIMEOUT"
   ]
  },
  {
   "cell_type": "code",
   "execution_count": 62,
   "metadata": {},
   "outputs": [],
   "source": [
    "client.close()\n",
    "cluster.close()"
   ]
  },
  {
   "cell_type": "code",
   "execution_count": null,
   "metadata": {},
   "outputs": [],
   "source": []
  }
 ],
 "metadata": {
  "kernelspec": {
   "display_name": "spatial",
   "language": "python",
   "name": "spatial"
  },
  "language_info": {
   "codemirror_mode": {
    "name": "ipython",
    "version": 3
   },
   "file_extension": ".py",
   "mimetype": "text/x-python",
   "name": "python",
   "nbconvert_exporter": "python",
   "pygments_lexer": "ipython3",
   "version": "3.9.12"
  }
 },
 "nbformat": 4,
 "nbformat_minor": 2
}
