/gpfs/commons/home/jsingh/.conda/envs/spatial/lib/python3.9/site-packages/distributed/cli/dask_worker.py:334: FutureWarning: The --nprocs flag will be removed in a future release. It has been renamed to --nworkers.
  warnings.warn(
2022-06-30 13:01:58,967 - distributed.nanny - INFO -         Start Nanny at: 'tcp://10.4.202.121:37254'
2022-06-30 13:01:58,995 - distributed.nanny - INFO -         Start Nanny at: 'tcp://10.4.202.121:35147'
2022-06-30 13:01:58,996 - distributed.nanny - INFO -         Start Nanny at: 'tcp://10.4.202.121:43890'
2022-06-30 13:01:59,029 - distributed.nanny - INFO -         Start Nanny at: 'tcp://10.4.202.121:36590'
2022-06-30 13:01:59,825 - distributed.diskutils - INFO - Found stale lock file and directory '/gpfs/commons/home/jsingh/NYGC-PySeq2500-Pipeline/src/post/dask-worker-space/worker-9axv8hn2', purging
2022-06-30 13:01:59,833 - distributed.diskutils - INFO - Found stale lock file and directory '/gpfs/commons/home/jsingh/NYGC-PySeq2500-Pipeline/src/post/dask-worker-space/worker-p3jglslp', purging
2022-06-30 13:02:05,925 - distributed.diskutils - INFO - Found stale lock file and directory '/gpfs/commons/home/jsingh/NYGC-PySeq2500-Pipeline/src/post/dask-worker-space/worker-bysr367n', purging
2022-06-30 13:02:05,941 - distributed.diskutils - INFO - Found stale lock file and directory '/gpfs/commons/home/jsingh/NYGC-PySeq2500-Pipeline/src/post/dask-worker-space/worker-6c77evet', purging
/gpfs/commons/home/jsingh/.conda/envs/spatial/lib/python3.9/contextlib.py:126: UserWarning: Creating scratch directories is taking a surprisingly long time. This is often due to running workers on a network file system. Consider specifying a local-directory to point workers to write scratch data to a local disk.
  next(self.gen)
/gpfs/commons/home/jsingh/.conda/envs/spatial/lib/python3.9/contextlib.py:126: UserWarning: Creating scratch directories is taking a surprisingly long time. This is often due to running workers on a network file system. Consider specifying a local-directory to point workers to write scratch data to a local disk.
  next(self.gen)
/gpfs/commons/home/jsingh/.conda/envs/spatial/lib/python3.9/contextlib.py:126: UserWarning: Creating scratch directories is taking a surprisingly long time. This is often due to running workers on a network file system. Consider specifying a local-directory to point workers to write scratch data to a local disk.
  next(self.gen)
2022-06-30 13:02:08,125 - distributed.worker - INFO -       Start worker at:   tcp://10.4.202.121:37488
2022-06-30 13:02:08,125 - distributed.worker - INFO -          Listening to:   tcp://10.4.202.121:37488
2022-06-30 13:02:08,125 - distributed.worker - INFO -          dashboard at:         10.4.202.121:42977
2022-06-30 13:02:08,125 - distributed.worker - INFO - Waiting to connect to:    tcp://10.4.200.39:35830
2022-06-30 13:02:08,125 - distributed.worker - INFO - -------------------------------------------------
2022-06-30 13:02:08,125 - distributed.worker - INFO -               Threads:                          3
2022-06-30 13:02:08,125 - distributed.worker - INFO -       Start worker at:   tcp://10.4.202.121:42356
2022-06-30 13:02:08,125 - distributed.worker - INFO -                Memory:                  29.80 GiB
2022-06-30 13:02:08,125 - distributed.worker - INFO -       Local Directory: /gpfs/commons/home/jsingh/NYGC-PySeq2500-Pipeline/src/post/dask-worker-space/worker-xijdniv7
2022-06-30 13:02:08,125 - distributed.worker - INFO -          Listening to:   tcp://10.4.202.121:42356
2022-06-30 13:02:08,125 - distributed.worker - INFO - -------------------------------------------------
2022-06-30 13:02:08,125 - distributed.worker - INFO -          dashboard at:         10.4.202.121:39722
2022-06-30 13:02:08,125 - distributed.worker - INFO - Waiting to connect to:    tcp://10.4.200.39:35830
2022-06-30 13:02:08,126 - distributed.worker - INFO - -------------------------------------------------
2022-06-30 13:02:08,126 - distributed.worker - INFO -               Threads:                          3
2022-06-30 13:02:08,126 - distributed.worker - INFO -       Start worker at:   tcp://10.4.202.121:37440
2022-06-30 13:02:08,128 - distributed.worker - INFO -                Memory:                  29.80 GiB
2022-06-30 13:02:08,128 - distributed.worker - INFO -       Local Directory: /gpfs/commons/home/jsingh/NYGC-PySeq2500-Pipeline/src/post/dask-worker-space/worker-17bmebmc
2022-06-30 13:02:08,128 - distributed.worker - INFO -          Listening to:   tcp://10.4.202.121:37440
2022-06-30 13:02:08,128 - distributed.worker - INFO -          dashboard at:         10.4.202.121:36127
2022-06-30 13:02:08,128 - distributed.worker - INFO - -------------------------------------------------
2022-06-30 13:02:08,128 - distributed.worker - INFO - Waiting to connect to:    tcp://10.4.200.39:35830
2022-06-30 13:02:08,128 - distributed.worker - INFO - -------------------------------------------------
2022-06-30 13:02:08,128 - distributed.worker - INFO -               Threads:                          3
2022-06-30 13:02:08,128 - distributed.worker - INFO -                Memory:                  29.80 GiB
2022-06-30 13:02:08,128 - distributed.worker - INFO -       Local Directory: /gpfs/commons/home/jsingh/NYGC-PySeq2500-Pipeline/src/post/dask-worker-space/worker-f17x34nv
2022-06-30 13:02:08,128 - distributed.worker - INFO - -------------------------------------------------
2022-06-30 13:02:08,159 - distributed.worker - INFO -         Registered to:    tcp://10.4.200.39:35830
2022-06-30 13:02:08,159 - distributed.worker - INFO - -------------------------------------------------
2022-06-30 13:02:08,160 - distributed.core - INFO - Starting established connection
2022-06-30 13:02:08,161 - distributed.worker - INFO -         Registered to:    tcp://10.4.200.39:35830
2022-06-30 13:02:08,161 - distributed.worker - INFO - -------------------------------------------------
2022-06-30 13:02:08,162 - distributed.core - INFO - Starting established connection
2022-06-30 13:02:08,166 - distributed.worker - INFO -         Registered to:    tcp://10.4.200.39:35830
2022-06-30 13:02:08,166 - distributed.worker - INFO - -------------------------------------------------
2022-06-30 13:02:08,167 - distributed.core - INFO - Starting established connection
2022-06-30 13:02:12,772 - distributed.worker - INFO -       Start worker at:   tcp://10.4.202.121:44352
2022-06-30 13:02:12,773 - distributed.worker - INFO -          Listening to:   tcp://10.4.202.121:44352
2022-06-30 13:02:12,773 - distributed.worker - INFO -          dashboard at:         10.4.202.121:43335
2022-06-30 13:02:12,773 - distributed.worker - INFO - Waiting to connect to:    tcp://10.4.200.39:35830
2022-06-30 13:02:12,773 - distributed.worker - INFO - -------------------------------------------------
2022-06-30 13:02:12,773 - distributed.worker - INFO -               Threads:                          3
2022-06-30 13:02:12,774 - distributed.worker - INFO -                Memory:                  29.80 GiB
2022-06-30 13:02:12,774 - distributed.worker - INFO -       Local Directory: /gpfs/commons/home/jsingh/NYGC-PySeq2500-Pipeline/src/post/dask-worker-space/worker-ndvmo6dh
2022-06-30 13:02:12,774 - distributed.worker - INFO - -------------------------------------------------
2022-06-30 13:02:12,807 - distributed.worker - INFO -         Registered to:    tcp://10.4.200.39:35830
2022-06-30 13:02:12,807 - distributed.worker - INFO - -------------------------------------------------
2022-06-30 13:02:12,808 - distributed.core - INFO - Starting established connection
2022-06-30 13:04:20,387 - distributed.worker - INFO - Connection to scheduler broken. Closing without reporting.  Status: Status.running
2022-06-30 13:04:20,388 - distributed.worker - INFO - Stopping worker at tcp://10.4.202.121:37488
2022-06-30 13:04:20,388 - distributed.worker - INFO - Connection to scheduler broken. Closing without reporting.  Status: Status.running
2022-06-30 13:04:20,389 - distributed.worker - INFO - Stopping worker at tcp://10.4.202.121:44352
2022-06-30 13:04:20,389 - distributed.worker - INFO - Connection to scheduler broken. Closing without reporting.  Status: Status.running
2022-06-30 13:04:20,388 - distributed.worker - INFO - Connection to scheduler broken. Closing without reporting.  Status: Status.running
2022-06-30 13:04:20,390 - distributed.worker - INFO - Stopping worker at tcp://10.4.202.121:37440
2022-06-30 13:04:20,390 - distributed.worker - INFO - Stopping worker at tcp://10.4.202.121:42356
2022-06-30 13:04:20,393 - distributed.worker - WARNING - Heartbeat to scheduler failed
Traceback (most recent call last):
  File "/gpfs/commons/home/jsingh/.conda/envs/spatial/lib/python3.9/site-packages/tornado/iostream.py", line 867, in _read_to_buffer
    bytes_read = self.read_from_fd(buf)
  File "/gpfs/commons/home/jsingh/.conda/envs/spatial/lib/python3.9/site-packages/tornado/iostream.py", line 1140, in read_from_fd
    return self.socket.recv_into(buf, len(buf))
ConnectionResetError: [Errno 104] Connection reset by peer

The above exception was the direct cause of the following exception:

Traceback (most recent call last):
  File "/gpfs/commons/home/jsingh/.conda/envs/spatial/lib/python3.9/site-packages/distributed/worker.py", line 1198, in heartbeat
    response = await retry_operation(
  File "/gpfs/commons/home/jsingh/.conda/envs/spatial/lib/python3.9/site-packages/distributed/utils_comm.py", line 381, in retry_operation
    return await retry(
  File "/gpfs/commons/home/jsingh/.conda/envs/spatial/lib/python3.9/site-packages/distributed/utils_comm.py", line 366, in retry
    return await coro()
  File "/gpfs/commons/home/jsingh/.conda/envs/spatial/lib/python3.9/site-packages/distributed/core.py", line 975, in send_recv_from_rpc
    return await send_recv(comm=comm, op=key, **kwargs)
  File "/gpfs/commons/home/jsingh/.conda/envs/spatial/lib/python3.9/site-packages/distributed/core.py", line 739, in send_recv
    response = await comm.read(deserializers=deserializers)
  File "/gpfs/commons/home/jsingh/.conda/envs/spatial/lib/python3.9/site-packages/distributed/comm/tcp.py", line 242, in read
    convert_stream_closed_error(self, e)
  File "/gpfs/commons/home/jsingh/.conda/envs/spatial/lib/python3.9/site-packages/distributed/comm/tcp.py", line 148, in convert_stream_closed_error
    raise CommClosedError(f"in {obj}: {exc.__class__.__name__}: {exc}") from exc
distributed.comm.core.CommClosedError: in <TCP (closed) ConnectionPool.heartbeat_worker local=tcp://10.4.202.121:44458 remote=tcp://10.4.200.39:35830>: ConnectionResetError: [Errno 104] Connection reset by peer
2022-06-30 13:04:20,393 - distributed.worker - WARNING - Heartbeat to scheduler failed
Traceback (most recent call last):
  File "/gpfs/commons/home/jsingh/.conda/envs/spatial/lib/python3.9/site-packages/tornado/iostream.py", line 867, in _read_to_buffer
    bytes_read = self.read_from_fd(buf)
  File "/gpfs/commons/home/jsingh/.conda/envs/spatial/lib/python3.9/site-packages/tornado/iostream.py", line 1140, in read_from_fd
    return self.socket.recv_into(buf, len(buf))
ConnectionResetError: [Errno 104] Connection reset by peer

The above exception was the direct cause of the following exception:

Traceback (most recent call last):
  File "/gpfs/commons/home/jsingh/.conda/envs/spatial/lib/python3.9/site-packages/distributed/worker.py", line 1198, in heartbeat
    response = await retry_operation(
  File "/gpfs/commons/home/jsingh/.conda/envs/spatial/lib/python3.9/site-packages/distributed/utils_comm.py", line 381, in retry_operation
    return await retry(
  File "/gpfs/commons/home/jsingh/.conda/envs/spatial/lib/python3.9/site-packages/distributed/utils_comm.py", line 366, in retry
    return await coro()
  File "/gpfs/commons/home/jsingh/.conda/envs/spatial/lib/python3.9/site-packages/distributed/core.py", line 975, in send_recv_from_rpc
    return await send_recv(comm=comm, op=key, **kwargs)
  File "/gpfs/commons/home/jsingh/.conda/envs/spatial/lib/python3.9/site-packages/distributed/core.py", line 739, in send_recv
    response = await comm.read(deserializers=deserializers)
  File "/gpfs/commons/home/jsingh/.conda/envs/spatial/lib/python3.9/site-packages/distributed/comm/tcp.py", line 242, in read
    convert_stream_closed_error(self, e)
  File "/gpfs/commons/home/jsingh/.conda/envs/spatial/lib/python3.9/site-packages/distributed/comm/tcp.py", line 148, in convert_stream_closed_error
    raise CommClosedError(f"in {obj}: {exc.__class__.__name__}: {exc}") from exc
distributed.comm.core.CommClosedError: in <TCP (closed) ConnectionPool.heartbeat_worker local=tcp://10.4.202.121:44826 remote=tcp://10.4.200.39:35830>: ConnectionResetError: [Errno 104] Connection reset by peer
2022-06-30 13:04:20,391 - distributed.worker - WARNING - Heartbeat to scheduler failed
Traceback (most recent call last):
  File "/gpfs/commons/home/jsingh/.conda/envs/spatial/lib/python3.9/site-packages/tornado/iostream.py", line 867, in _read_to_buffer
    bytes_read = self.read_from_fd(buf)
  File "/gpfs/commons/home/jsingh/.conda/envs/spatial/lib/python3.9/site-packages/tornado/iostream.py", line 1140, in read_from_fd
    return self.socket.recv_into(buf, len(buf))
ConnectionResetError: [Errno 104] Connection reset by peer

The above exception was the direct cause of the following exception:

Traceback (most recent call last):
  File "/gpfs/commons/home/jsingh/.conda/envs/spatial/lib/python3.9/site-packages/distributed/worker.py", line 1198, in heartbeat
    response = await retry_operation(
  File "/gpfs/commons/home/jsingh/.conda/envs/spatial/lib/python3.9/site-packages/distributed/utils_comm.py", line 381, in retry_operation
    return await retry(
  File "/gpfs/commons/home/jsingh/.conda/envs/spatial/lib/python3.9/site-packages/distributed/utils_comm.py", line 366, in retry
    return await coro()
  File "/gpfs/commons/home/jsingh/.conda/envs/spatial/lib/python3.9/site-packages/distributed/core.py", line 975, in send_recv_from_rpc
    return await send_recv(comm=comm, op=key, **kwargs)
  File "/gpfs/commons/home/jsingh/.conda/envs/spatial/lib/python3.9/site-packages/distributed/core.py", line 739, in send_recv
    response = await comm.read(deserializers=deserializers)
  File "/gpfs/commons/home/jsingh/.conda/envs/spatial/lib/python3.9/site-packages/distributed/comm/tcp.py", line 242, in read
    convert_stream_closed_error(self, e)
  File "/gpfs/commons/home/jsingh/.conda/envs/spatial/lib/python3.9/site-packages/distributed/comm/tcp.py", line 148, in convert_stream_closed_error
    raise CommClosedError(f"in {obj}: {exc.__class__.__name__}: {exc}") from exc
distributed.comm.core.CommClosedError: in <TCP (closed) ConnectionPool.heartbeat_worker local=tcp://10.4.202.121:44460 remote=tcp://10.4.200.39:35830>: ConnectionResetError: [Errno 104] Connection reset by peer
2022-06-30 13:04:20,393 - distributed.worker - WARNING - Heartbeat to scheduler failed
Traceback (most recent call last):
  File "/gpfs/commons/home/jsingh/.conda/envs/spatial/lib/python3.9/site-packages/tornado/iostream.py", line 867, in _read_to_buffer
    bytes_read = self.read_from_fd(buf)
  File "/gpfs/commons/home/jsingh/.conda/envs/spatial/lib/python3.9/site-packages/tornado/iostream.py", line 1140, in read_from_fd
    return self.socket.recv_into(buf, len(buf))
ConnectionResetError: [Errno 104] Connection reset by peer

The above exception was the direct cause of the following exception:

Traceback (most recent call last):
  File "/gpfs/commons/home/jsingh/.conda/envs/spatial/lib/python3.9/site-packages/distributed/worker.py", line 1198, in heartbeat
    response = await retry_operation(
  File "/gpfs/commons/home/jsingh/.conda/envs/spatial/lib/python3.9/site-packages/distributed/utils_comm.py", line 381, in retry_operation
    return await retry(
  File "/gpfs/commons/home/jsingh/.conda/envs/spatial/lib/python3.9/site-packages/distributed/utils_comm.py", line 366, in retry
    return await coro()
  File "/gpfs/commons/home/jsingh/.conda/envs/spatial/lib/python3.9/site-packages/distributed/core.py", line 975, in send_recv_from_rpc
    return await send_recv(comm=comm, op=key, **kwargs)
  File "/gpfs/commons/home/jsingh/.conda/envs/spatial/lib/python3.9/site-packages/distributed/core.py", line 739, in send_recv
    response = await comm.read(deserializers=deserializers)
  File "/gpfs/commons/home/jsingh/.conda/envs/spatial/lib/python3.9/site-packages/distributed/comm/tcp.py", line 242, in read
    convert_stream_closed_error(self, e)
  File "/gpfs/commons/home/jsingh/.conda/envs/spatial/lib/python3.9/site-packages/distributed/comm/tcp.py", line 148, in convert_stream_closed_error
    raise CommClosedError(f"in {obj}: {exc.__class__.__name__}: {exc}") from exc
distributed.comm.core.CommClosedError: in <TCP (closed) ConnectionPool.heartbeat_worker local=tcp://10.4.202.121:44664 remote=tcp://10.4.200.39:35830>: ConnectionResetError: [Errno 104] Connection reset by peer
2022-06-30 13:04:22,570 - distributed.client - ERROR - 
ConnectionRefusedError: [Errno 111] Connection refused

The above exception was the direct cause of the following exception:

Traceback (most recent call last):
  File "/gpfs/commons/home/jsingh/.conda/envs/spatial/lib/python3.9/site-packages/distributed/comm/core.py", line 289, in connect
    comm = await asyncio.wait_for(
  File "/gpfs/commons/home/jsingh/.conda/envs/spatial/lib/python3.9/asyncio/tasks.py", line 479, in wait_for
    return fut.result()
  File "/gpfs/commons/home/jsingh/.conda/envs/spatial/lib/python3.9/site-packages/distributed/comm/tcp.py", line 451, in connect
    convert_stream_closed_error(self, e)
  File "/gpfs/commons/home/jsingh/.conda/envs/spatial/lib/python3.9/site-packages/distributed/comm/tcp.py", line 148, in convert_stream_closed_error
    raise CommClosedError(f"in {obj}: {exc.__class__.__name__}: {exc}") from exc
distributed.comm.core.CommClosedError: in <distributed.comm.tcp.TCPConnector object at 0x7fc78824a6a0>: ConnectionRefusedError: [Errno 111] Connection refused

During handling of the above exception, another exception occurred:

Traceback (most recent call last):
  File "/gpfs/commons/home/jsingh/.conda/envs/spatial/lib/python3.9/site-packages/distributed/utils.py", line 761, in wrapper
    return await func(*args, **kwargs)
  File "/gpfs/commons/home/jsingh/.conda/envs/spatial/lib/python3.9/site-packages/distributed/client.py", line 1225, in _reconnect
    await self._ensure_connected(timeout=timeout)
  File "/gpfs/commons/home/jsingh/.conda/envs/spatial/lib/python3.9/site-packages/distributed/client.py", line 1255, in _ensure_connected
    comm = await connect(
  File "/gpfs/commons/home/jsingh/.conda/envs/spatial/lib/python3.9/site-packages/distributed/comm/core.py", line 313, in connect
    await asyncio.sleep(backoff)
  File "/gpfs/commons/home/jsingh/.conda/envs/spatial/lib/python3.9/asyncio/tasks.py", line 652, in sleep
    return await future
asyncio.exceptions.CancelledError
2022-06-30 13:04:22,564 - distributed.client - ERROR - 
ConnectionRefusedError: [Errno 111] Connection refused

The above exception was the direct cause of the following exception:

Traceback (most recent call last):
  File "/gpfs/commons/home/jsingh/.conda/envs/spatial/lib/python3.9/site-packages/distributed/comm/core.py", line 289, in connect
    comm = await asyncio.wait_for(
  File "/gpfs/commons/home/jsingh/.conda/envs/spatial/lib/python3.9/asyncio/tasks.py", line 479, in wait_for
    return fut.result()
  File "/gpfs/commons/home/jsingh/.conda/envs/spatial/lib/python3.9/site-packages/distributed/comm/tcp.py", line 451, in connect
    convert_stream_closed_error(self, e)
  File "/gpfs/commons/home/jsingh/.conda/envs/spatial/lib/python3.9/site-packages/distributed/comm/tcp.py", line 148, in convert_stream_closed_error
    raise CommClosedError(f"in {obj}: {exc.__class__.__name__}: {exc}") from exc
distributed.comm.core.CommClosedError: in <distributed.comm.tcp.TCPConnector object at 0x7f946ee6ddf0>: ConnectionRefusedError: [Errno 111] Connection refused

During handling of the above exception, another exception occurred:

Traceback (most recent call last):
  File "/gpfs/commons/home/jsingh/.conda/envs/spatial/lib/python3.9/site-packages/distributed/utils.py", line 761, in wrapper
    return await func(*args, **kwargs)
  File "/gpfs/commons/home/jsingh/.conda/envs/spatial/lib/python3.9/site-packages/distributed/client.py", line 1225, in _reconnect
    await self._ensure_connected(timeout=timeout)
  File "/gpfs/commons/home/jsingh/.conda/envs/spatial/lib/python3.9/site-packages/distributed/client.py", line 1255, in _ensure_connected
    comm = await connect(
  File "/gpfs/commons/home/jsingh/.conda/envs/spatial/lib/python3.9/site-packages/distributed/comm/core.py", line 313, in connect
    await asyncio.sleep(backoff)
  File "/gpfs/commons/home/jsingh/.conda/envs/spatial/lib/python3.9/asyncio/tasks.py", line 652, in sleep
    return await future
asyncio.exceptions.CancelledError
2022-06-30 13:04:22,523 - distributed.client - ERROR - 
ConnectionRefusedError: [Errno 111] Connection refused

The above exception was the direct cause of the following exception:

Traceback (most recent call last):
  File "/gpfs/commons/home/jsingh/.conda/envs/spatial/lib/python3.9/site-packages/distributed/comm/core.py", line 289, in connect
    comm = await asyncio.wait_for(
  File "/gpfs/commons/home/jsingh/.conda/envs/spatial/lib/python3.9/asyncio/tasks.py", line 479, in wait_for
    return fut.result()
  File "/gpfs/commons/home/jsingh/.conda/envs/spatial/lib/python3.9/site-packages/distributed/comm/tcp.py", line 451, in connect
    convert_stream_closed_error(self, e)
  File "/gpfs/commons/home/jsingh/.conda/envs/spatial/lib/python3.9/site-packages/distributed/comm/tcp.py", line 148, in convert_stream_closed_error
    raise CommClosedError(f"in {obj}: {exc.__class__.__name__}: {exc}") from exc
distributed.comm.core.CommClosedError: in <distributed.comm.tcp.TCPConnector object at 0x7f805407a070>: ConnectionRefusedError: [Errno 111] Connection refused

During handling of the above exception, another exception occurred:

Traceback (most recent call last):
  File "/gpfs/commons/home/jsingh/.conda/envs/spatial/lib/python3.9/site-packages/distributed/utils.py", line 761, in wrapper
    return await func(*args, **kwargs)
  File "/gpfs/commons/home/jsingh/.conda/envs/spatial/lib/python3.9/site-packages/distributed/client.py", line 1225, in _reconnect
    await self._ensure_connected(timeout=timeout)
  File "/gpfs/commons/home/jsingh/.conda/envs/spatial/lib/python3.9/site-packages/distributed/client.py", line 1255, in _ensure_connected
    comm = await connect(
  File "/gpfs/commons/home/jsingh/.conda/envs/spatial/lib/python3.9/site-packages/distributed/comm/core.py", line 313, in connect
    await asyncio.sleep(backoff)
  File "/gpfs/commons/home/jsingh/.conda/envs/spatial/lib/python3.9/asyncio/tasks.py", line 652, in sleep
    return await future
asyncio.exceptions.CancelledError

Traceback (most recent call last):
  File "/gpfs/commons/home/jsingh/.conda/envs/spatial/lib/python3.9/site-packages/tornado/iostream.py", line 867, in _read_to_buffer
    bytes_read = self.read_from_fd(buf)
  File "/gpfs/commons/home/jsingh/.conda/envs/spatial/lib/python3.9/site-packages/tornado/iostream.py", line 1140, in read_from_fd
    return self.socket.recv_into(buf, len(buf))
ConnectionResetError: [Errno 104] Connection reset by peer

The above exception was the direct cause of the following exception:

Traceback (most recent call last):
  File "/gpfs/commons/home/jsingh/.conda/envs/spatial/lib/python3.9/site-packages/distributed/client.py", line 1406, in _handle_report
    msgs = await self.scheduler_comm.comm.read()
  File "/gpfs/commons/home/jsingh/.conda/envs/spatial/lib/python3.9/site-packages/distributed/comm/tcp.py", line 242, in read
    convert_stream_closed_error(self, e)
  File "/gpfs/commons/home/jsingh/.conda/envs/spatial/lib/python3.9/site-packages/distributed/comm/tcp.py", line 148, in convert_stream_closed_error
    raise CommClosedError(f"in {obj}: {exc.__class__.__name__}: {exc}") from exc
distributed.comm.core.CommClosedError: in <TCP (closed) Client->Scheduler local=tcp://10.4.202.121:44614 remote=tcp://10.4.200.39:35830>: ConnectionResetError: [Errno 104] Connection reset by peer

During handling of the above exception, another exception occurred:

Traceback (most recent call last):
  File "/gpfs/commons/home/jsingh/.conda/envs/spatial/lib/python3.9/site-packages/distributed/utils.py", line 761, in wrapper
    return await func(*args, **kwargs)
  File "/gpfs/commons/home/jsingh/.conda/envs/spatial/lib/python3.9/site-packages/distributed/client.py", line 1414, in _handle_report
    await self._reconnect()
  File "/gpfs/commons/home/jsingh/.conda/envs/spatial/lib/python3.9/site-packages/distributed/utils.py", line 761, in wrapper
    return await func(*args, **kwargs)
  File "/gpfs/commons/home/jsingh/.conda/envs/spatial/lib/python3.9/site-packages/distributed/client.py", line 1225, in _reconnect
    await self._ensure_connected(timeout=timeout)
  File "/gpfs/commons/home/jsingh/.conda/envs/spatial/lib/python3.9/site-packages/distributed/client.py", line 1255, in _ensure_connected
    comm = await connect(
  File "/gpfs/commons/home/jsingh/.conda/envs/spatial/lib/python3.9/site-packages/distributed/comm/core.py", line 313, in connect
    await asyncio.sleep(backoff)
  File "/gpfs/commons/home/jsingh/.conda/envs/spatial/lib/python3.9/asyncio/tasks.py", line 652, in sleep
    return await future
asyncio.exceptions.CancelledError
2022-06-30 13:04:22,581 - distributed.client - ERROR - 
ConnectionRefusedError: [Errno 111] Connection refused

The above exception was the direct cause of the following exception:

Traceback (most recent call last):
  File "/gpfs/commons/home/jsingh/.conda/envs/spatial/lib/python3.9/site-packages/distributed/comm/core.py", line 289, in connect
    comm = await asyncio.wait_for(
  File "/gpfs/commons/home/jsingh/.conda/envs/spatial/lib/python3.9/asyncio/tasks.py", line 479, in wait_for
    return fut.result()
  File "/gpfs/commons/home/jsingh/.conda/envs/spatial/lib/python3.9/site-packages/distributed/comm/tcp.py", line 451, in connect
    convert_stream_closed_error(self, e)
  File "/gpfs/commons/home/jsingh/.conda/envs/spatial/lib/python3.9/site-packages/distributed/comm/tcp.py", line 148, in convert_stream_closed_error
    raise CommClosedError(f"in {obj}: {exc.__class__.__name__}: {exc}") from exc
distributed.comm.core.CommClosedError: in <distributed.comm.tcp.TCPConnector object at 0x7ff7c2218b80>: ConnectionRefusedError: [Errno 111] Connection refused

During handling of the above exception, another exception occurred:

Traceback (most recent call last):
  File "/gpfs/commons/home/jsingh/.conda/envs/spatial/lib/python3.9/site-packages/distributed/utils.py", line 761, in wrapper
    return await func(*args, **kwargs)
  File "/gpfs/commons/home/jsingh/.conda/envs/spatial/lib/python3.9/site-packages/distributed/client.py", line 1225, in _reconnect
    await self._ensure_connected(timeout=timeout)
  File "/gpfs/commons/home/jsingh/.conda/envs/spatial/lib/python3.9/site-packages/distributed/client.py", line 1255, in _ensure_connected
    comm = await connect(
  File "/gpfs/commons/home/jsingh/.conda/envs/spatial/lib/python3.9/site-packages/distributed/comm/core.py", line 313, in connect
    await asyncio.sleep(backoff)
  File "/gpfs/commons/home/jsingh/.conda/envs/spatial/lib/python3.9/asyncio/tasks.py", line 652, in sleep
    return await future
asyncio.exceptions.CancelledError

Traceback (most recent call last):
  File "/gpfs/commons/home/jsingh/.conda/envs/spatial/lib/python3.9/site-packages/distributed/comm/tcp.py", line 226, in read
    frames_nbytes = await stream.read_bytes(fmt_size)
tornado.iostream.StreamClosedError: Stream is closed

The above exception was the direct cause of the following exception:

Traceback (most recent call last):
  File "/gpfs/commons/home/jsingh/.conda/envs/spatial/lib/python3.9/site-packages/distributed/client.py", line 1406, in _handle_report
    msgs = await self.scheduler_comm.comm.read()
  File "/gpfs/commons/home/jsingh/.conda/envs/spatial/lib/python3.9/site-packages/distributed/comm/tcp.py", line 242, in read
    convert_stream_closed_error(self, e)
  File "/gpfs/commons/home/jsingh/.conda/envs/spatial/lib/python3.9/site-packages/distributed/comm/tcp.py", line 150, in convert_stream_closed_error
    raise CommClosedError(f"in {obj}: {exc}") from exc
distributed.comm.core.CommClosedError: in <TCP (closed) Client->Scheduler local=tcp://10.4.202.121:44622 remote=tcp://10.4.200.39:35830>: Stream is closed

During handling of the above exception, another exception occurred:

Traceback (most recent call last):
  File "/gpfs/commons/home/jsingh/.conda/envs/spatial/lib/python3.9/site-packages/distributed/utils.py", line 761, in wrapper
    return await func(*args, **kwargs)
  File "/gpfs/commons/home/jsingh/.conda/envs/spatial/lib/python3.9/site-packages/distributed/client.py", line 1414, in _handle_report
    await self._reconnect()
  File "/gpfs/commons/home/jsingh/.conda/envs/spatial/lib/python3.9/site-packages/distributed/utils.py", line 761, in wrapper
    return await func(*args, **kwargs)
  File "/gpfs/commons/home/jsingh/.conda/envs/spatial/lib/python3.9/site-packages/distributed/client.py", line 1225, in _reconnect
    await self._ensure_connected(timeout=timeout)
  File "/gpfs/commons/home/jsingh/.conda/envs/spatial/lib/python3.9/site-packages/distributed/client.py", line 1255, in _ensure_connected
    comm = await connect(
  File "/gpfs/commons/home/jsingh/.conda/envs/spatial/lib/python3.9/site-packages/distributed/comm/core.py", line 313, in connect
    await asyncio.sleep(backoff)
  File "/gpfs/commons/home/jsingh/.conda/envs/spatial/lib/python3.9/asyncio/tasks.py", line 652, in sleep
    return await future
asyncio.exceptions.CancelledError

Traceback (most recent call last):
  File "/gpfs/commons/home/jsingh/.conda/envs/spatial/lib/python3.9/site-packages/tornado/iostream.py", line 867, in _read_to_buffer
    bytes_read = self.read_from_fd(buf)
  File "/gpfs/commons/home/jsingh/.conda/envs/spatial/lib/python3.9/site-packages/tornado/iostream.py", line 1140, in read_from_fd
    return self.socket.recv_into(buf, len(buf))
ConnectionResetError: [Errno 104] Connection reset by peer

The above exception was the direct cause of the following exception:

Traceback (most recent call last):
  File "/gpfs/commons/home/jsingh/.conda/envs/spatial/lib/python3.9/site-packages/distributed/client.py", line 1406, in _handle_report
    msgs = await self.scheduler_comm.comm.read()
  File "/gpfs/commons/home/jsingh/.conda/envs/spatial/lib/python3.9/site-packages/distributed/comm/tcp.py", line 242, in read
    convert_stream_closed_error(self, e)
  File "/gpfs/commons/home/jsingh/.conda/envs/spatial/lib/python3.9/site-packages/distributed/comm/tcp.py", line 148, in convert_stream_closed_error
    raise CommClosedError(f"in {obj}: {exc.__class__.__name__}: {exc}") from exc
distributed.comm.core.CommClosedError: in <TCP (closed) Client->Scheduler local=tcp://10.4.202.121:44608 remote=tcp://10.4.200.39:35830>: ConnectionResetError: [Errno 104] Connection reset by peer

During handling of the above exception, another exception occurred:

Traceback (most recent call last):
  File "/gpfs/commons/home/jsingh/.conda/envs/spatial/lib/python3.9/site-packages/distributed/utils.py", line 761, in wrapper
    return await func(*args, **kwargs)
  File "/gpfs/commons/home/jsingh/.conda/envs/spatial/lib/python3.9/site-packages/distributed/client.py", line 1414, in _handle_report
    await self._reconnect()
  File "/gpfs/commons/home/jsingh/.conda/envs/spatial/lib/python3.9/site-packages/distributed/utils.py", line 761, in wrapper
    return await func(*args, **kwargs)
  File "/gpfs/commons/home/jsingh/.conda/envs/spatial/lib/python3.9/site-packages/distributed/client.py", line 1225, in _reconnect
    await self._ensure_connected(timeout=timeout)
  File "/gpfs/commons/home/jsingh/.conda/envs/spatial/lib/python3.9/site-packages/distributed/client.py", line 1255, in _ensure_connected
    comm = await connect(
  File "/gpfs/commons/home/jsingh/.conda/envs/spatial/lib/python3.9/site-packages/distributed/comm/core.py", line 313, in connect
    await asyncio.sleep(backoff)
  File "/gpfs/commons/home/jsingh/.conda/envs/spatial/lib/python3.9/asyncio/tasks.py", line 652, in sleep
    return await future
asyncio.exceptions.CancelledError

Traceback (most recent call last):
  File "/gpfs/commons/home/jsingh/.conda/envs/spatial/lib/python3.9/site-packages/distributed/comm/tcp.py", line 226, in read
    frames_nbytes = await stream.read_bytes(fmt_size)
tornado.iostream.StreamClosedError: Stream is closed

The above exception was the direct cause of the following exception:

Traceback (most recent call last):
  File "/gpfs/commons/home/jsingh/.conda/envs/spatial/lib/python3.9/site-packages/distributed/client.py", line 1406, in _handle_report
    msgs = await self.scheduler_comm.comm.read()
  File "/gpfs/commons/home/jsingh/.conda/envs/spatial/lib/python3.9/site-packages/distributed/comm/tcp.py", line 242, in read
    convert_stream_closed_error(self, e)
  File "/gpfs/commons/home/jsingh/.conda/envs/spatial/lib/python3.9/site-packages/distributed/comm/tcp.py", line 150, in convert_stream_closed_error
    raise CommClosedError(f"in {obj}: {exc}") from exc
distributed.comm.core.CommClosedError: in <TCP (closed) Client->Scheduler local=tcp://10.4.202.121:44620 remote=tcp://10.4.200.39:35830>: Stream is closed

During handling of the above exception, another exception occurred:

Traceback (most recent call last):
  File "/gpfs/commons/home/jsingh/.conda/envs/spatial/lib/python3.9/site-packages/distributed/utils.py", line 761, in wrapper
    return await func(*args, **kwargs)
  File "/gpfs/commons/home/jsingh/.conda/envs/spatial/lib/python3.9/site-packages/distributed/client.py", line 1414, in _handle_report
    await self._reconnect()
  File "/gpfs/commons/home/jsingh/.conda/envs/spatial/lib/python3.9/site-packages/distributed/utils.py", line 761, in wrapper
    return await func(*args, **kwargs)
  File "/gpfs/commons/home/jsingh/.conda/envs/spatial/lib/python3.9/site-packages/distributed/client.py", line 1225, in _reconnect
    await self._ensure_connected(timeout=timeout)
  File "/gpfs/commons/home/jsingh/.conda/envs/spatial/lib/python3.9/site-packages/distributed/client.py", line 1255, in _ensure_connected
    comm = await connect(
  File "/gpfs/commons/home/jsingh/.conda/envs/spatial/lib/python3.9/site-packages/distributed/comm/core.py", line 313, in connect
    await asyncio.sleep(backoff)
  File "/gpfs/commons/home/jsingh/.conda/envs/spatial/lib/python3.9/asyncio/tasks.py", line 652, in sleep
    return await future
asyncio.exceptions.CancelledError
2022-06-30 13:04:24,686 - distributed.client - ERROR - 
ConnectionRefusedError: [Errno 111] Connection refused

The above exception was the direct cause of the following exception:

Traceback (most recent call last):
  File "/gpfs/commons/home/jsingh/.conda/envs/spatial/lib/python3.9/site-packages/distributed/comm/core.py", line 289, in connect
    comm = await asyncio.wait_for(
  File "/gpfs/commons/home/jsingh/.conda/envs/spatial/lib/python3.9/asyncio/tasks.py", line 479, in wait_for
    return fut.result()
  File "/gpfs/commons/home/jsingh/.conda/envs/spatial/lib/python3.9/site-packages/distributed/comm/tcp.py", line 451, in connect
    convert_stream_closed_error(self, e)
  File "/gpfs/commons/home/jsingh/.conda/envs/spatial/lib/python3.9/site-packages/distributed/comm/tcp.py", line 148, in convert_stream_closed_error
    raise CommClosedError(f"in {obj}: {exc.__class__.__name__}: {exc}") from exc
distributed.comm.core.CommClosedError: in <distributed.comm.tcp.TCPConnector object at 0x7f8055a65cd0>: ConnectionRefusedError: [Errno 111] Connection refused

During handling of the above exception, another exception occurred:

Traceback (most recent call last):
  File "/gpfs/commons/home/jsingh/.conda/envs/spatial/lib/python3.9/site-packages/distributed/utils.py", line 761, in wrapper
    return await func(*args, **kwargs)
  File "/gpfs/commons/home/jsingh/.conda/envs/spatial/lib/python3.9/site-packages/distributed/client.py", line 1225, in _reconnect
    await self._ensure_connected(timeout=timeout)
  File "/gpfs/commons/home/jsingh/.conda/envs/spatial/lib/python3.9/site-packages/distributed/client.py", line 1255, in _ensure_connected
    comm = await connect(
  File "/gpfs/commons/home/jsingh/.conda/envs/spatial/lib/python3.9/site-packages/distributed/comm/core.py", line 313, in connect
    await asyncio.sleep(backoff)
  File "/gpfs/commons/home/jsingh/.conda/envs/spatial/lib/python3.9/asyncio/tasks.py", line 652, in sleep
    return await future
asyncio.exceptions.CancelledError
2022-06-30 13:04:24,688 - distributed.client - ERROR - 
ConnectionRefusedError: [Errno 111] Connection refused

The above exception was the direct cause of the following exception:

Traceback (most recent call last):
  File "/gpfs/commons/home/jsingh/.conda/envs/spatial/lib/python3.9/site-packages/distributed/comm/core.py", line 289, in connect
    comm = await asyncio.wait_for(
  File "/gpfs/commons/home/jsingh/.conda/envs/spatial/lib/python3.9/asyncio/tasks.py", line 479, in wait_for
    return fut.result()
  File "/gpfs/commons/home/jsingh/.conda/envs/spatial/lib/python3.9/site-packages/distributed/comm/tcp.py", line 451, in connect
    convert_stream_closed_error(self, e)
  File "/gpfs/commons/home/jsingh/.conda/envs/spatial/lib/python3.9/site-packages/distributed/comm/tcp.py", line 148, in convert_stream_closed_error
    raise CommClosedError(f"in {obj}: {exc.__class__.__name__}: {exc}") from exc
distributed.comm.core.CommClosedError: in <distributed.comm.tcp.TCPConnector object at 0x7fc785f62370>: ConnectionRefusedError: [Errno 111] Connection refused

During handling of the above exception, another exception occurred:

Traceback (most recent call last):
  File "/gpfs/commons/home/jsingh/.conda/envs/spatial/lib/python3.9/site-packages/distributed/utils.py", line 761, in wrapper
    return await func(*args, **kwargs)
  File "/gpfs/commons/home/jsingh/.conda/envs/spatial/lib/python3.9/site-packages/distributed/client.py", line 1225, in _reconnect
    await self._ensure_connected(timeout=timeout)
  File "/gpfs/commons/home/jsingh/.conda/envs/spatial/lib/python3.9/site-packages/distributed/client.py", line 1255, in _ensure_connected
    comm = await connect(
  File "/gpfs/commons/home/jsingh/.conda/envs/spatial/lib/python3.9/site-packages/distributed/comm/core.py", line 313, in connect
    await asyncio.sleep(backoff)
  File "/gpfs/commons/home/jsingh/.conda/envs/spatial/lib/python3.9/asyncio/tasks.py", line 652, in sleep
    return await future
asyncio.exceptions.CancelledError
2022-06-30 13:04:24,695 - distributed.client - ERROR - 
ConnectionRefusedError: [Errno 111] Connection refused

The above exception was the direct cause of the following exception:

Traceback (most recent call last):
  File "/gpfs/commons/home/jsingh/.conda/envs/spatial/lib/python3.9/site-packages/distributed/comm/core.py", line 289, in connect
    comm = await asyncio.wait_for(
  File "/gpfs/commons/home/jsingh/.conda/envs/spatial/lib/python3.9/asyncio/tasks.py", line 479, in wait_for
    return fut.result()
  File "/gpfs/commons/home/jsingh/.conda/envs/spatial/lib/python3.9/site-packages/distributed/comm/tcp.py", line 451, in connect
    convert_stream_closed_error(self, e)
  File "/gpfs/commons/home/jsingh/.conda/envs/spatial/lib/python3.9/site-packages/distributed/comm/tcp.py", line 148, in convert_stream_closed_error
    raise CommClosedError(f"in {obj}: {exc.__class__.__name__}: {exc}") from exc
distributed.comm.core.CommClosedError: in <distributed.comm.tcp.TCPConnector object at 0x7f946c65f370>: ConnectionRefusedError: [Errno 111] Connection refused

During handling of the above exception, another exception occurred:

Traceback (most recent call last):
  File "/gpfs/commons/home/jsingh/.conda/envs/spatial/lib/python3.9/site-packages/distributed/utils.py", line 761, in wrapper
    return await func(*args, **kwargs)
  File "/gpfs/commons/home/jsingh/.conda/envs/spatial/lib/python3.9/site-packages/distributed/client.py", line 1225, in _reconnect
    await self._ensure_connected(timeout=timeout)
  File "/gpfs/commons/home/jsingh/.conda/envs/spatial/lib/python3.9/site-packages/distributed/client.py", line 1255, in _ensure_connected
    comm = await connect(
  File "/gpfs/commons/home/jsingh/.conda/envs/spatial/lib/python3.9/site-packages/distributed/comm/core.py", line 313, in connect
    await asyncio.sleep(backoff)
  File "/gpfs/commons/home/jsingh/.conda/envs/spatial/lib/python3.9/asyncio/tasks.py", line 652, in sleep
    return await future
asyncio.exceptions.CancelledError

Traceback (most recent call last):
  File "/gpfs/commons/home/jsingh/.conda/envs/spatial/lib/python3.9/site-packages/distributed/comm/tcp.py", line 226, in read
    frames_nbytes = await stream.read_bytes(fmt_size)
tornado.iostream.StreamClosedError: Stream is closed

The above exception was the direct cause of the following exception:

Traceback (most recent call last):
  File "/gpfs/commons/home/jsingh/.conda/envs/spatial/lib/python3.9/site-packages/distributed/client.py", line 1406, in _handle_report
    msgs = await self.scheduler_comm.comm.read()
  File "/gpfs/commons/home/jsingh/.conda/envs/spatial/lib/python3.9/site-packages/distributed/comm/tcp.py", line 242, in read
    convert_stream_closed_error(self, e)
  File "/gpfs/commons/home/jsingh/.conda/envs/spatial/lib/python3.9/site-packages/distributed/comm/tcp.py", line 150, in convert_stream_closed_error
    raise CommClosedError(f"in {obj}: {exc}") from exc
distributed.comm.core.CommClosedError: in <TCP (closed) Client->Scheduler local=tcp://10.4.202.121:44612 remote=tcp://10.4.200.39:35830>: Stream is closed

During handling of the above exception, another exception occurred:

Traceback (most recent call last):
  File "/gpfs/commons/home/jsingh/.conda/envs/spatial/lib/python3.9/site-packages/distributed/utils.py", line 761, in wrapper
    return await func(*args, **kwargs)
  File "/gpfs/commons/home/jsingh/.conda/envs/spatial/lib/python3.9/site-packages/distributed/client.py", line 1414, in _handle_report
    await self._reconnect()
  File "/gpfs/commons/home/jsingh/.conda/envs/spatial/lib/python3.9/site-packages/distributed/utils.py", line 761, in wrapper
    return await func(*args, **kwargs)
  File "/gpfs/commons/home/jsingh/.conda/envs/spatial/lib/python3.9/site-packages/distributed/client.py", line 1225, in _reconnect
    await self._ensure_connected(timeout=timeout)
  File "/gpfs/commons/home/jsingh/.conda/envs/spatial/lib/python3.9/site-packages/distributed/client.py", line 1255, in _ensure_connected
    comm = await connect(
  File "/gpfs/commons/home/jsingh/.conda/envs/spatial/lib/python3.9/site-packages/distributed/comm/core.py", line 313, in connect
    await asyncio.sleep(backoff)
  File "/gpfs/commons/home/jsingh/.conda/envs/spatial/lib/python3.9/asyncio/tasks.py", line 652, in sleep
    return await future
asyncio.exceptions.CancelledError

Traceback (most recent call last):
  File "/gpfs/commons/home/jsingh/.conda/envs/spatial/lib/python3.9/site-packages/tornado/iostream.py", line 867, in _read_to_buffer
    bytes_read = self.read_from_fd(buf)
  File "/gpfs/commons/home/jsingh/.conda/envs/spatial/lib/python3.9/site-packages/tornado/iostream.py", line 1140, in read_from_fd
    return self.socket.recv_into(buf, len(buf))
ConnectionResetError: [Errno 104] Connection reset by peer

The above exception was the direct cause of the following exception:

Traceback (most recent call last):
  File "/gpfs/commons/home/jsingh/.conda/envs/spatial/lib/python3.9/site-packages/distributed/client.py", line 1406, in _handle_report
    msgs = await self.scheduler_comm.comm.read()
  File "/gpfs/commons/home/jsingh/.conda/envs/spatial/lib/python3.9/site-packages/distributed/comm/tcp.py", line 242, in read
    convert_stream_closed_error(self, e)
  File "/gpfs/commons/home/jsingh/.conda/envs/spatial/lib/python3.9/site-packages/distributed/comm/tcp.py", line 148, in convert_stream_closed_error
    raise CommClosedError(f"in {obj}: {exc.__class__.__name__}: {exc}") from exc
distributed.comm.core.CommClosedError: in <TCP (closed) Client->Scheduler local=tcp://10.4.202.121:44624 remote=tcp://10.4.200.39:35830>: ConnectionResetError: [Errno 104] Connection reset by peer

During handling of the above exception, another exception occurred:

Traceback (most recent call last):
  File "/gpfs/commons/home/jsingh/.conda/envs/spatial/lib/python3.9/site-packages/distributed/utils.py", line 761, in wrapper
    return await func(*args, **kwargs)
  File "/gpfs/commons/home/jsingh/.conda/envs/spatial/lib/python3.9/site-packages/distributed/client.py", line 1414, in _handle_report
    await self._reconnect()
  File "/gpfs/commons/home/jsingh/.conda/envs/spatial/lib/python3.9/site-packages/distributed/utils.py", line 761, in wrapper
    return await func(*args, **kwargs)
  File "/gpfs/commons/home/jsingh/.conda/envs/spatial/lib/python3.9/site-packages/distributed/client.py", line 1225, in _reconnect
    await self._ensure_connected(timeout=timeout)
  File "/gpfs/commons/home/jsingh/.conda/envs/spatial/lib/python3.9/site-packages/distributed/client.py", line 1255, in _ensure_connected
    comm = await connect(
  File "/gpfs/commons/home/jsingh/.conda/envs/spatial/lib/python3.9/site-packages/distributed/comm/core.py", line 313, in connect
    await asyncio.sleep(backoff)
  File "/gpfs/commons/home/jsingh/.conda/envs/spatial/lib/python3.9/asyncio/tasks.py", line 652, in sleep
    return await future
asyncio.exceptions.CancelledError
2022-06-30 13:04:24,699 - distributed.client - ERROR - 
ConnectionRefusedError: [Errno 111] Connection refused

The above exception was the direct cause of the following exception:

Traceback (most recent call last):
  File "/gpfs/commons/home/jsingh/.conda/envs/spatial/lib/python3.9/site-packages/distributed/comm/core.py", line 289, in connect
    comm = await asyncio.wait_for(
  File "/gpfs/commons/home/jsingh/.conda/envs/spatial/lib/python3.9/asyncio/tasks.py", line 479, in wait_for
    return fut.result()
  File "/gpfs/commons/home/jsingh/.conda/envs/spatial/lib/python3.9/site-packages/distributed/comm/tcp.py", line 451, in connect
    convert_stream_closed_error(self, e)
  File "/gpfs/commons/home/jsingh/.conda/envs/spatial/lib/python3.9/site-packages/distributed/comm/tcp.py", line 148, in convert_stream_closed_error
    raise CommClosedError(f"in {obj}: {exc.__class__.__name__}: {exc}") from exc
distributed.comm.core.CommClosedError: in <distributed.comm.tcp.TCPConnector object at 0x7ff7fe2350d0>: ConnectionRefusedError: [Errno 111] Connection refused

During handling of the above exception, another exception occurred:

Traceback (most recent call last):
  File "/gpfs/commons/home/jsingh/.conda/envs/spatial/lib/python3.9/site-packages/distributed/utils.py", line 761, in wrapper
    return await func(*args, **kwargs)
  File "/gpfs/commons/home/jsingh/.conda/envs/spatial/lib/python3.9/site-packages/distributed/client.py", line 1225, in _reconnect
    await self._ensure_connected(timeout=timeout)
  File "/gpfs/commons/home/jsingh/.conda/envs/spatial/lib/python3.9/site-packages/distributed/client.py", line 1255, in _ensure_connected
    comm = await connect(
  File "/gpfs/commons/home/jsingh/.conda/envs/spatial/lib/python3.9/site-packages/distributed/comm/core.py", line 313, in connect
    await asyncio.sleep(backoff)
  File "/gpfs/commons/home/jsingh/.conda/envs/spatial/lib/python3.9/asyncio/tasks.py", line 652, in sleep
    return await future
asyncio.exceptions.CancelledError
2022-06-30 13:04:24,704 - distributed.nanny - INFO - Worker closed
2022-06-30 13:04:24,705 - distributed.nanny - INFO - Worker closed
2022-06-30 13:04:24,705 - distributed.nanny - ERROR - Worker process died unexpectedly
2022-06-30 13:04:24,707 - distributed.nanny - ERROR - Worker process died unexpectedly

Traceback (most recent call last):
  File "/gpfs/commons/home/jsingh/.conda/envs/spatial/lib/python3.9/site-packages/tornado/iostream.py", line 867, in _read_to_buffer
    bytes_read = self.read_from_fd(buf)
  File "/gpfs/commons/home/jsingh/.conda/envs/spatial/lib/python3.9/site-packages/tornado/iostream.py", line 1140, in read_from_fd
    return self.socket.recv_into(buf, len(buf))
ConnectionResetError: [Errno 104] Connection reset by peer

The above exception was the direct cause of the following exception:

Traceback (most recent call last):
  File "/gpfs/commons/home/jsingh/.conda/envs/spatial/lib/python3.9/site-packages/distributed/client.py", line 1406, in _handle_report
    msgs = await self.scheduler_comm.comm.read()
  File "/gpfs/commons/home/jsingh/.conda/envs/spatial/lib/python3.9/site-packages/distributed/comm/tcp.py", line 242, in read
    convert_stream_closed_error(self, e)
  File "/gpfs/commons/home/jsingh/.conda/envs/spatial/lib/python3.9/site-packages/distributed/comm/tcp.py", line 148, in convert_stream_closed_error
    raise CommClosedError(f"in {obj}: {exc.__class__.__name__}: {exc}") from exc
distributed.comm.core.CommClosedError: in <TCP (closed) Client->Scheduler local=tcp://10.4.202.121:44606 remote=tcp://10.4.200.39:35830>: ConnectionResetError: [Errno 104] Connection reset by peer

During handling of the above exception, another exception occurred:

Traceback (most recent call last):
  File "/gpfs/commons/home/jsingh/.conda/envs/spatial/lib/python3.9/site-packages/distributed/utils.py", line 761, in wrapper
    return await func(*args, **kwargs)
  File "/gpfs/commons/home/jsingh/.conda/envs/spatial/lib/python3.9/site-packages/distributed/client.py", line 1414, in _handle_report
    await self._reconnect()
  File "/gpfs/commons/home/jsingh/.conda/envs/spatial/lib/python3.9/site-packages/distributed/utils.py", line 761, in wrapper
    return await func(*args, **kwargs)
  File "/gpfs/commons/home/jsingh/.conda/envs/spatial/lib/python3.9/site-packages/distributed/client.py", line 1225, in _reconnect
    await self._ensure_connected(timeout=timeout)
  File "/gpfs/commons/home/jsingh/.conda/envs/spatial/lib/python3.9/site-packages/distributed/client.py", line 1255, in _ensure_connected
    comm = await connect(
  File "/gpfs/commons/home/jsingh/.conda/envs/spatial/lib/python3.9/site-packages/distributed/comm/core.py", line 313, in connect
    await asyncio.sleep(backoff)
  File "/gpfs/commons/home/jsingh/.conda/envs/spatial/lib/python3.9/asyncio/tasks.py", line 652, in sleep
    return await future
asyncio.exceptions.CancelledError
2022-06-30 13:04:24,715 - distributed.nanny - INFO - Worker closed
2022-06-30 13:04:24,717 - distributed.nanny - ERROR - Worker process died unexpectedly

Traceback (most recent call last):
  File "/gpfs/commons/home/jsingh/.conda/envs/spatial/lib/python3.9/site-packages/tornado/iostream.py", line 867, in _read_to_buffer
    bytes_read = self.read_from_fd(buf)
  File "/gpfs/commons/home/jsingh/.conda/envs/spatial/lib/python3.9/site-packages/tornado/iostream.py", line 1140, in read_from_fd
    return self.socket.recv_into(buf, len(buf))
ConnectionResetError: [Errno 104] Connection reset by peer

The above exception was the direct cause of the following exception:

Traceback (most recent call last):
  File "/gpfs/commons/home/jsingh/.conda/envs/spatial/lib/python3.9/site-packages/distributed/client.py", line 1406, in _handle_report
    msgs = await self.scheduler_comm.comm.read()
  File "/gpfs/commons/home/jsingh/.conda/envs/spatial/lib/python3.9/site-packages/distributed/comm/tcp.py", line 242, in read
    convert_stream_closed_error(self, e)
  File "/gpfs/commons/home/jsingh/.conda/envs/spatial/lib/python3.9/site-packages/distributed/comm/tcp.py", line 148, in convert_stream_closed_error
    raise CommClosedError(f"in {obj}: {exc.__class__.__name__}: {exc}") from exc
distributed.comm.core.CommClosedError: in <TCP (closed) Client->Scheduler local=tcp://10.4.202.121:44618 remote=tcp://10.4.200.39:35830>: ConnectionResetError: [Errno 104] Connection reset by peer

During handling of the above exception, another exception occurred:

Traceback (most recent call last):
  File "/gpfs/commons/home/jsingh/.conda/envs/spatial/lib/python3.9/site-packages/distributed/utils.py", line 761, in wrapper
    return await func(*args, **kwargs)
  File "/gpfs/commons/home/jsingh/.conda/envs/spatial/lib/python3.9/site-packages/distributed/client.py", line 1414, in _handle_report
    await self._reconnect()
  File "/gpfs/commons/home/jsingh/.conda/envs/spatial/lib/python3.9/site-packages/distributed/utils.py", line 761, in wrapper
    return await func(*args, **kwargs)
  File "/gpfs/commons/home/jsingh/.conda/envs/spatial/lib/python3.9/site-packages/distributed/client.py", line 1225, in _reconnect
    await self._ensure_connected(timeout=timeout)
  File "/gpfs/commons/home/jsingh/.conda/envs/spatial/lib/python3.9/site-packages/distributed/client.py", line 1255, in _ensure_connected
    comm = await connect(
  File "/gpfs/commons/home/jsingh/.conda/envs/spatial/lib/python3.9/site-packages/distributed/comm/core.py", line 313, in connect
    await asyncio.sleep(backoff)
  File "/gpfs/commons/home/jsingh/.conda/envs/spatial/lib/python3.9/asyncio/tasks.py", line 652, in sleep
    return await future
asyncio.exceptions.CancelledError
2022-06-30 13:04:24,724 - distributed.nanny - INFO - Worker closed
2022-06-30 13:04:24,726 - distributed.nanny - ERROR - Worker process died unexpectedly
2022-06-30 13:04:25,256 - distributed.nanny - INFO - Closing Nanny at 'tcp://10.4.202.121:36590'.
2022-06-30 13:04:25,285 - distributed.nanny - INFO - Closing Nanny at 'tcp://10.4.202.121:35147'.
2022-06-30 13:04:25,287 - distributed.nanny - INFO - Closing Nanny at 'tcp://10.4.202.121:37254'.
2022-06-30 13:04:25,317 - distributed.nanny - INFO - Closing Nanny at 'tcp://10.4.202.121:43890'.
2022-06-30 13:04:25,320 - distributed.dask_worker - INFO - End worker
